Workbook

Sheet Read Me & Markers
A1: Winning Creatives – Meta ad account 2009539369903270 (Shopify: w1rbg9wu, USD)
A2: Period: 16 Apr 2026 – 16 Oct 2026 · Source: Meta Ads (platform-reported, account default attribution) · Pulled 16 Oct 2026
A4: Account baseline (6 months)
A5: Amount spent ($) | B5: 432627.08 | C5: Source: Meta Ads, account level, 16 Apr–16 Oct 2026
A6: Purchases | B6: 7180
A7: Purchase value ($) | B7: 438530.28
A8: Purchase ROAS | B8: =B7/B5 -> 1.013645
A9: Cost per purchase ($) | B9: =B5/B6 -> 60.254468
A10: Impressions | B10: 4078096
A11: CPM ($) | B11: 106.09
A12: CTR (link) | B12: 0.04281
A13: Frequency | B13: 3.97
A14: Adds to cart | B14: 14635
A15: Checkouts initiated | B15: 18196
A17: Winner thresholds (yellow = edit to re-score the "All Ads" sheet)
A18: Min spend – proven ($) | B18: 1000 | C18: Assumption (default) – ≈17× account CPA, so a result is not luck
A19: Min purchases – proven | B19: 20 | C19: Assumption (default) – Statistical floor
A20: Proven winner: ROAS ≥ | B20: 1.3 | C20: Assumption (default) – ≈1.3× account average ROAS (1.01x)
A21: Strong performer: ROAS ≥ | B21: 1.1 | C21: Assumption (default) – ~10% above account average
A22: Scale workhorse: min spend ($) | B22: 10000 | C22: Assumption (default) – Carries big budget at ≥ breakeven
A23: Scale workhorse: ROAS ≥ | B23: 1 | C23: Assumption (default) – Breakeven on first purchase
A24: Promising: min spend ($) | B24: 250 | C24: Assumption (default) – ≈4× CPA
A25: Promising: min purchases | B25: 5 | C25: Assumption (default) –
A26: Promising: ROAS ≥ | B26: 1.3 | C26: Assumption (default) – Needs more spend to prove
A28: Tiers | C28: # ads
A29: A. Proven winner | B29: Spend ≥ B18, purchases ≥ B19, ROAS ≥ B20 | C29: =COUNTIF('All Ads 6mo'!B:B,"A. Proven winner") -> 13
A30: B. Strong performer | B30: Spend ≥ B18, purchases ≥ B19, ROAS ≥ B21 | C30: =COUNTIF('All Ads 6mo'!B:B,"B. Strong performer") -> 9
A31: C. Scale workhorse | B31: Spend ≥ B22, ROAS ≥ B23 (volume carrier) | C31: =COUNTIF('All Ads 6mo'!B:B,"C. Scale workhorse") -> 2
A32: D. Promising (needs more spend) | B32: Spend B24–B18, purchases ≥ B25, ROAS ≥ B26 | C32: =COUNTIF('All Ads 6mo'!B:B,"D. Promising (needs more spend)") -> 18
A34: Secondary markers (context, not pass/fail)
A35: • Cost per purchase vs account avg (lower = better)
A36: • CTR (link) – scroll-stopping power / message-market fit
A37: • Video play rate = video plays ÷ impressions (hook proxy)
A38: • ThruPlay rate = ThruPlays ÷ video plays (hold)
A39: • CPM – auction cost; high CPM + high ROAS = premium audience
A40: • Frequency – >2.5 on prospecting signals fatigue
A41: • Monthly trend – ROAS across months it spent (see Monthly Trend tab)
A42: • Funnel: adds to cart / checkouts initiated per purchase
A44: Notes
A45: • Purchase ROAS / value are Meta platform-reported (account default attribution window). Not reconciled with Shopify or Triple Whale.
...

Sheet Winners
A1: Tier | B1: Ad name | C1: Ad ID | D1: Campaign | E1: Ad set | F1: Status | G1: Created | H1: Product | I1: Format | J1: Visual ID | K1: Amount spent ($) | L1: Purchases | M1: Purchase value ($) | N1: Purchase ROAS | O1: ROAS vs acct avg | P1: Cost per purchase ($) | Q1: CPA vs acct avg | R1: CTR (link) | S1: CPM ($) | T1: Frequency | U1: Impressions | V1: Link clicks | W1: Adds to cart | X1: Checkouts initiated | Y1: Video plays | Z1: ThruPlays | AA1: Video play rate | AB1: ThruPlay rate | AC1: Monthly ROAS (months ≥$100 spend) | AD1: Headline | AE1: Primary text | AF1: Description | AG1: CTA | AH1: Video ID | AI1: Creative ID | AJ1: Facebook post
A2: A. Proven winner | B2: - Video - Ad - 1 - Copy | C2: 120243619709580341 | D2: 5. NMN Scaling Campaign (CBO) Feb 14 2026 | E2: 4. Feb 27 (9. Feb 9 USA 19-21) | F2: PAUSED | G2: 2026-02-28 | H2: NMN Complex | I2: Video (existing post) | J2: 632447272 | K2: 2401.61 | L2: 71 | M2: 4981.57 | N2: 2.074263 | O2: =N2/'Read Me & Markers'!$B$8 -> 2.0463407 | P2: 33.83 | Q2: =P2/'Read Me & Markers'!$B$9 -> 0.56145214 | R2: 0.03077266 | S2: 66.94 | T2: 2.257062 | U2: 35876 | V2: 1104 | W2: 202 | X2: 163 | Y2: 29419 | Z2: 1263 | AA2: =IF(U2>0,Y2/U2,0) -> 0.82001895 | AB2: =IF(Y2>0,Z2/Y2,0) -> 0.042931439 | AC2: Apr* 3.24x ($747) | May 1.55x ($1,654) | AD2: (from existing post) | AE2: (from existing post) | AF2: Say goodbye to tiredness! NAD+ levels drop with age, but our NMN Complex helps boost them for clean energy & focus. | AG2: SHOP_NOW / post CTA | AI2: 798275069992277 | AJ2: https://www.facebook.com/1012373248616002_122115188331199246
A3: A. Proven winner | B3: - Video - Ad -2 | C3: 120244413721500341 | D3: 4. N2 Testing Campaign (CBO) Jan 27 2026 | E3: 57. March 16 USA 4-6 | F3: PAUSED | G3: 2026-03-15 | H3: NMN Complex | I3: Video (existing post) | J3: 626804201 | K3: 1159.35 | L3: 34 | M3: 2398.76 | N3: 2.069056 | O3: =N3/'Read Me & Markers'!$B$8 -> 2.0412038 | P3: 34.1 | Q3: =P3/'Read Me & Markers'!$B$9 -> 0.56593314 | R3: 0.0257704 | S3: 62.9 | T3: 1.791776 | U3: 18432 | V3: 475 | W3: 99 | X3: 80 | Y3: 16419 | Z3: 959 | AA3: =IF(U3>0,Y3/U3,0) -> 0.89078776 | AB3: =IF(Y3>0,Z3/Y3,0) -> 0.058407942 | AC3: Jun 2.25x ($1,010) | Jul 0.84x ($149) | AD3: (from existing post) | AE3: (from existing post) | AF3: Say goodbye to tiredness! NAD+ levels drop with age, but our NMN Complex helps boost them for clean energy & focus. | AG3: SHOP_NOW / post CTA | AI3: 2393502171176026 | AJ3: https://www.facebook.com/1012373248616002_122132796645199246
A4: A. Proven winner | B4: 19 | C4: 120253373064280341 | D4: 8. NMN Testing Campaign (CBO) June 21 2026 | E4: 57. Mixed Batch | 15Aug 2026 | F4: ACTIVE | G4: 2026-08-15 | H4: NMN Complex | I4: Image | J4: img d67840aa | K4: 1409.73 | L4: 26 | M4: 2297.06 | N4: 1.629433 | O4: =N4/'Read Me & Markers'!$B$8 -> 1.6074987 | P4: 54.22 | Q4: =P4/'Read Me & Markers'!$B$9 -> 0.89985028 | R4: 0.0126388 | S4: 42.42 | T4: 2.21673 | U4: 33231 | V4: 420 | W4: 38 | X4: 74 | Y4: 0 | Z4: 0 | AA4: =IF(U4>0,Y4/U4,0) -> 0 | AB4: =IF(Y4>0,Z4/Y4,0) -> 0 | AC4: Aug 2.06x ($110) | Sep 1.71x ($1,024) | Oct* 1.14x ($276) | AD4: SUMMER SALE! 75% OFF TODAY ONLY! | AE4: Feeling more tired as you age? It's not "just aging." Your NAD+ levels naturally drop — the molecule your cells need for clean, steady energy. Our NMN Complex helps support those levels so you can feel energized, focused, and clear again. | AF4: Say goodbye to tiredness! NAD+ levels drop with age, but our NMN Complex helps boost them for clean energy & focus. | AG4: SHOP_NOW | AI4: 1650351506688920 | AJ4: https://www.facebook.com/1012373248616002_122136309765199246
A5: A. Proven winner | B5: - Video - Ad - 1 | C5: 120243390597510341 | D5: 4. N2 Testing Campaign (CBO) Jan 27 2026 | E5: 24. Feb 23 USA 10-12 | F5: PAUSED | G5: 2026-02-23 | H5: NMN Complex | I5: Video (existing post) | J5: 634374960 | K5: 6572.42 | L5: 163 | M5: 10470.66 | N5: 1.593121 | O5: =N5/'Read Me & Markers'!$B$8 -> 1.5716755 | P5: 40.32 | Q5: =P5/'Read Me & Markers'!$B$9 -> 0.669162 | R5: 0.04816885 | S5: 126.69 | T5: 1.176257 | U5: 51880 | V5: 2499 | W5: 411 | X5: 338 | Y5: 49111 | Z5: 9571 | AA5: =IF(U5>0,Y5/U5,0) -> 0.94662683 | AB5: =IF(Y5>0,Z5/Y5,0) -> 0.19488506 | AC5: Apr* 1.41x ($2,952) | May 1.74x ($3,620) | AD5: (from existing post) | AE5: (from existing post) | AF5: Say goodbye to tiredness! NAD+ levels drop with age, but our NMN Complex helps boost them for clean energy & focus. | AG5: SHOP_NOW / post CTA | AI5: 936535988715973 | AJ5: https://www.facebook.com/1012373248616002_122114599707199246
A6: A. Proven winner | B6: - Video - Ad - 2 | C6: 120250187515990341 | D6: 4. N2 Testing Campaign (CBO) Jan 27 2026 | E6: 139. June 10 USA 19-21 | F6: PAUSED | G6: 2026-06-10 | H6: NMN Complex | I6: Video | J6: 720588181 | K6: 1493.23 | L6: 38 | M6: 2376.66 | N6: 1.591624 | O6: =N6/'Read Me & Markers'!$B$8 -> 1.5701986 | P6: 39.3 | Q6: =P6/'Read Me & Markers'!$B$9 -> 0.65223379 | R6: 0.02006015 | S6: 51.03 | T6: 1.684338 | U6: 29262 | V6: 587 | W6: 99 | X6: 82 | Y6: 25250 | Z6: 1753 | AA6: =IF(U6>0,Y6/U6,0) -> 0.86289386 | AB6: =IF(Y6>0,Z6/Y6,0) -> 0.069425743 | AC6: Jun 1.67x ($1,403) | AD6: SPRING SALE! 75% OFF TODAY ONLY! | AE6: Feeling more tired as you age? It's not "just aging." Your NAD+ levels naturally drop — the molecule your cells need for clean, steady energy. Our NMN Complex helps support those levels so you can feel energized, focused, and clear again. | AF6: Say goodbye to tiredness! NAD+ levels drop with age, but our NMN Complex helps boost them for clean energy & focus. | AG6: SHOP_NOW | AH6: 2238052663607310 | AI6: 27180240411634181 | AJ6: https://www.facebook.com/1012373248616002_122129137371199246
A7: A. Proven winner | B7: - Video - Ad -2 | C7: 120242733176260341 | D7: 4. N2 Testing Campaign (CBO) Jan 27 2026 | E7: 11. Feb 6 USA 19-21 | F7: PAUSED | G7: 2026-02-06 | H7: NMN Complex | I7: Video (existing post) | J7: 626417952 | K7: 1703.96 | L7: 37 | M7: 2604.41 | N7: 1.528446 | O7: =N7/'Read Me & Markers'!$B$8 -> 1.5078711 | P7: 46.05 | Q7: =P7/'Read Me & Markers'!$B$9 -> 0.76425868 | R7: 0.02451674 | S7: 66.95 | T7: 1.662986 | U7: 25452 | V7: 624 | W7: 118 | X7: 94 | Y7: 21957 | Z7: 1224 | AA7: =IF(U7>0,Y7/U7,0) -> 0.8626827 | AB7: =IF(Y7>0,Z7/Y7,0) -> 0.05574532 | AC7: Apr* 3.70x ($179) | May 1.27x ($1,525) | AD7: (from existing post) | AE7: (from existing post) | AF7: Say goodbye to tiredness! NAD+ levels drop with age, but our NMN Complex helps boost them for clean energy & focus. | AG7: SHOP_NOW / post CTA | AI7: 927499036457312 | AJ7: https://www.facebook.com/1012373248616002_122111829975199246
A8: A. Proven winner | B8: - Video - Ad - 1 - Copy | C8: 120243669805030341 | D8: 5. NMN Scaling Campaign (CBO) Feb 14 2026 | E8: 5. Feb 28 (24. Feb 23 USA 10-12) | F8: PAUSED | G8: 2026-02-28 | H8: NMN Complex | I8: Video (existing post) | J8: 634374960 | K8: 36342.32 | L8: 866 | M8: 53976.31 | N8: 1.485219 | O8: =N8/'Read Me & Markers'!$B$8 -> 1.465226 | P8: 41.97 | Q8: =P8/'Read Me & Markers'!$B$9 -> 0.69654586 | R8: 0.04720497 | S8: 112.66 | T8: 1.770856 | U8: 322572 | V8: 15227 | W8: 2557 | X8: 1905 | Y8: 297219 | Z8: 57700 | AA8: =IF(U8>0,Y8/U8,0) -> 0.92140359 | AB8: =IF(Y8>0,Z8/Y8,0) -> 0.19413295 | AC8: Apr* 1.78x ($12,015) | May 1.34x ($24,328) | AD8: (from existing post) | AE8: (from existing post) | AF8: Say goodbye to tiredness! NAD+ levels drop with age, but our NMN Complex helps boost them for clean energy & focus. | AG8: SHOP_NOW / post CTA | AI8: 1607918377022076 | AJ8: https://www.facebook.com/1012373248616002_122115191559199246
A9: A. Proven winner | B9: - Video - Ad -12 | C9: 120245650660800341 | D9: 1. Testing Campaign (CBO) Campaign Nov 8 2025 | E9: 76. March 24 USA - 10-12 | F9: PAUSED | G9: 2026-04-09 | H9: Astaxanthin | I9: Video (existing post) | J9: 668732739 | K9: 1200 | L9: 30 | M9: 1763.76 | N9: 1.4698 | O9: =N9/'Read Me & Markers'!$B$8 -> 1.4500145 | P9: 40 | Q9: =P9/'Read Me & Markers'!$B$9 -> 0.66385119 | R9: 0.03207706 | S9: 56.11 | T9: 1.5085 | U9: 21386 | V9: 686 | W9: 91 | X9: 72 | Y9: 19234 | Z9: 1414 | AA9: =IF(U9>0,Y9/U9,0) -> 0.89937342 | AB9: =IF(Y9>0,Z9/Y9,0) -> 0.073515649 | AC9: Apr* 0.70x ($165) | May 1.59x ($1,035) | AD9: (from existing post) | AE9: (from existing post) | AF9: ✨ Protect Your Skin from Within! ✨ Boost your natural glow, energy, and recovery with 12mg of pure, algae-sourced Astaxanthin — one of nature's most powerful antioxidants. 💧 Reduce fine lines & improve skin texture ⚡ Fight fatigue and support cellular energy 🛡️ Defend against UV damage and environmental stress. Just one easy-to-take softgel a day with food keeps your skin, body, and energy in top form — naturally. | AG9: SHOP_NOW / post CTA | AI9: 1257594603167800 | AJ9: https://www.facebook.com/1012373248616002_122121415473199246
A10: A. Proven winner | B10: - Video - Ad - 1 | C10: 120243675534840341 | D10: 4. N2 Testing Campaign (CBO) Jan 27 2026 | E10: 28. Feb 28 USA 1-3 | F10: PAUSED | G10: 2026-02-28 | H10: NMN Complex | I10: Video (existing post) | J10: 627853673 | K10: 7578.6 | L10: 157 | M10: 10583.75 | N10: 1.396531 | O10: =N10/'Read Me & Markers'!$B$8 -> 1.3777318 | P10: 48.27 | Q10: =P10/'Read Me & Markers'!$B$9 -> 0.80110242 | R10: 0.0258393 | S10: 65.41 | T10: 2.18825 | U10: 115870 | V10: 2994 | W10: 486 | X10: 359 | Y10: 102172 | Z10: 7261 | AA10: =IF(U10>0,Y10/U10,0) -> 0.88178131 | AB10: =IF(Y10>0,Z10/Y10,0) -> 0.071066437 | AC10: Jun 1.42x ($6,691) | Jul 1.25x ($881) | AD10: (from existing post) | AE10: (from existing post) | AF10: Say goodbye to tiredness! NAD+ levels drop with age, but our NMN Complex helps boost them for clean energy & focus. | AG10: SHOP_NOW / post CTA | AI10: 925935393130728 | AJ10: https://www.facebook.com/1012373248616002_122115312795199246
A11: A. Proven winner | B11: - Video - Ad - 3 | C11: 120242308889180341 | D11: 4. N2 Testing Campaign (CBO) Jan 27 2026 | E11: Jan 27 USA 7-9 | F11: WITH_ISSUES | G11: 2026-01-27 | H11: NMN Complex | I11: Video | J11: 623055237 | K11: 16480.85 | L11: 395 | M11: 22893.89 | N11: 1.389121 | O11: =N11/'Read Me & Markers'!$B$8 -> 1.3704216 | P11: 41.72 | Q11: =P11/'Read Me & Markers'!$B$9 -> 0.69239679 | R11: 0.06919453 | S11: 87.84 | T11: 1.09498 | U11: 187616 | V11: 12982 | W11: 1023 | X11: 790 | Y11: 180193 | Z11: 71708 | AA11: =IF(U11>0,Y11/U11,0) -> 0.96043514 | AB11: =IF(Y11>0,Z11/Y11,0) -> 0.39795109 | AC11: Apr* 1.45x ($2,466) | May 1.38x ($14,015) | AD11: NEW YEAR FLASH SALE! 75% OFF TODAY ONLY! | AE11: Feeling more tired as you age? It's not "just aging." Your NAD+ levels naturally drop — the molecule your cells need for clean, steady energy. Our NMN Complex helps support those levels so you can feel energized, focused, and clear again. | AF11: Say goodbye to tiredness! NAD+ levels drop with age, but our NMN Complex helps boost them for clean energy & focus. | AG11: SHOP_NOW | AH11: 728562103409957 | AI11: 877567944890755 | AJ11: https://www.facebook.com/1012373248616002_122109427737199246
A12: A. Proven winner | B12: - Video - Ad - 1 | C12: 120242733176430341 | D12: 4. N2 Testing Campaign (CBO) Jan 27 2026 | E12: 42. Feb 6 USA 10-12 | F12: PAUSED | G12: 2026-02-06 | H12: NMN Complex | I12: Video (existing post) | J12: 626826360 | K12: 4060.67 | L12: 86 | M12: 5594.95 | N12: 1.377839 | O12: =N12/'Read Me & Markers'!$B$8 -> 1.3592915 | P12: 47.22 | Q12: =P12/'Read Me & Markers'!$B$9 -> 0.78367632 | R12: 0.04588548 | S12: 89.32 | T12: 1.194393 | U12: 45461 | V12: 2086 | W12: 252 | X12: 193 | Y12: 42881 | Z12: 10606 | AA12: =IF(U12>0,Y12/U12,0) -> 0.94324806 | AB12: =IF(Y12>0,Z12/Y12,0) -> 0.24733565 | AC12: Apr* 1.47x ($2,364) | May 1.26x ($1,697) | AD12: (from existing post) | AE12: (from existing post) | AF12: Say goodbye to tiredness! NAD+ levels drop with age, but our NMN Complex helps boost them for clean energy & focus. | AG12: SHOP_NOW / post CTA | AI12: 787593873688069 | AJ12: https://www.facebook.com/1012373248616002_122111830011199246
A13: A. Proven winner | B13: - Video - Ad - 1 | C13: 120243701969760341 | D13: 4. N2 Testing Campaign (CBO) Jan 27 2026 | E13: 38. Mar 3 USA - 10-12 | F13: PAUSED | G13: 2026-03-01 | H13: NMN Complex | I13: Video (existing post) | J13: 626417952 | K13: 2654.79 | L13: 58 | M13: 3592.47 | N13: 1.353203 | O13: =N13/'Read Me & Markers'!$B$8 -> 1.3349871 | P13: 45.77 | Q13: =P13/'Read Me & Markers'!$B$9 -> 0.75961172 | R13: 0.04463756 | S13: 71.65 | T13: 1.10008 | U13: 37054 | V13: 1654 | W13: 133 | X13: 107 | Y13: 35610 | Z13: 9008 | AA13: =IF(U13>0,Y13/U13,0) -> 0.96102985 | AB13: =IF(Y13>0,Z13/Y13,0) -> 0.25296265 | AC13: Apr* 1.40x ($1,967) | May 1.23x ($688) | AD13: (from existing post) | AE13: (from existing post) | AF13: Say goodbye to tiredness! NAD+ levels drop with age, but our NMN Complex helps boost them for clean energy & focus. | AG13: SHOP_NOW / post CTA | AI13: 942978621724725 | AJ13: https://www.facebook.com/1012373248616002_122115516579199246
A14: A. Proven winner | B14: - Video - Ad -2 - Copy | C14: 120246199037900341 | D14: 5. NMN Scaling Campaign (CBO) Feb 14 2026 | E14: 18. April 20 (11. Feb 6 USA 19-21) - 2 | F14: PAUSED | G14: 2026-04-20 | H14: NMN Complex | I14: Video (existing post) | J14: 626417952 | K14: 1021.63 | L14: 21 | M14: 1370.4 | N14: 1.341386 | O14: =N14/'Read Me & Markers'!$B$8 -> 1.3233292 | P14: 48.65 | Q14: =P14/'Read Me & Markers'!$B$9 -> 0.807409 | R14: 0.02303805 | S14: 50.62 | T14: 1.923751 | U14: 20184 | V14: 465 | W14: 75 | X14: 63 | Y14: 16041 | Z14: 573 | AA14: =IF(U14>0,Y14/U14,0) -> 0.79473841 | AB14: =IF(Y14>0,Z14/Y14,0) -> 0.035720965 | AC14: May 1.32x ($975) | AD14: (from existing post) | AE14: (from existing post) | AF14: Say goodbye to tiredness! NAD+ levels drop with age, but our NMN Complex helps boost them for clean energy & focus. | AG14: SHOP_NOW / post CTA | AI14: 1697922741377115 | AJ14: https://www.facebook.com/1012373248616002_122123043327199246
A15: B. Strong performer | B15: - Video - Ad - 1 - Copy | C15: 120243160670300341 | D15: 5. NMN Scaling Campaign (CBO) Feb 14 2026 | E15: 2. Feb 19 (12. Feb 6 USA 16-18) | F15: PAUSED | G15: 2026-02-19 | H15: NMN Complex | I15: Video (existing post) | J15: 626804201 | K15: 13539.24 | L15: 262 | M15: 16514.4 | N15: 1.219744 | O15: =N15/'Read Me & Markers'!$B$8 -> 1.2033246 | P15: 51.68 | Q15: =P15/'Read Me & Markers'!$B$9 -> 0.85769573 | R15: 0.02535233 | S15: 69.64 | T15: 2.204808 | U15: 194420 | V15: 4929 | W15: 763 | X15: 626 | Y15: 173129 | Z15: 7139 | AA15: =IF(U15>0,Y15/U15,0) -> 0.89048966 | AB15: =IF(Y15>0,Z15/Y15,0) -> 0.041235148 | AC15: Apr* 1.73x ($1,009) | May 1.18x ($12,530) | AD15: (from existing post) | AE15: (from existing post) | AF15: Say goodbye to tiredness! NAD+ levels drop with age, but our NMN Complex helps boost them for clean energy & focus. | AG15: SHOP_NOW / post CTA | AI15: 1277267117282690 | AJ15: https://www.facebook.com/1012373248616002_122122956429199246
A16: B. Strong performer | B16: - Video - Ad - 2 | C16: 120249839070250341 | D16: 7. N2 Testing Campaign (CBO) May 28 2026 | E16: 18. June 7 USA 10-12 | F16: PAUSED | G16: 2026-06-07 | H16: NMN Complex | I16: Video | J16: 712703739 | K16: 1757.8 | L16: 29 | M16: 2143.87 | N16: 1.219633 | O16: =N16/'Read Me & Markers'!$B$8 -> 1.2032151 | P16: 60.61 | Q16: =P16/'Read Me & Markers'!$B$9 -> 1.0059005 | R16: 0.03686007 | S16: 99.99 | T16: 1.364377 | U16: 17580 | V16: 648 | W16: 80 | X16: 75 | Y16: 16230 | Z16: 3662 | AA16: =IF(U16>0,Y16/U16,0) -> 0.92320819 | AB16: =IF(Y16>0,Z16/Y16,0) -> 0.22563155 | AC16: Jun 1.22x ($1,758) | AD16: SPRING SALE! 75% OFF TODAY ONLY! | AE16: Feeling more tired as you age? It's not "just aging." Your NAD+ levels naturally drop — the molecule your cells need for clean, steady energy. Our NMN Complex helps support those levels so you can feel energized, focused, and clear again. | AF16: Say goodbye to tiredness! NAD+ levels drop with age, but our NMN Complex helps boost them for clean energy & focus. | AG16: SHOP_NOW | AH16: 1320986519439826 | AI16: 1361742352499613 | AJ16: https://www.facebook.com/1012373248616002_122128729047199246
A17: B. Strong performer | B17: - Video - Ad -2 | C17: 120243701969710341 | D17: 4. N2 Testing Campaign (CBO) Jan 27 2026 | E17: 36. Mar 3 USA - 4-6 | F17: PAUSED | G17: 2026-03-01 | H17: NMN Complex | I17: Video (existing post) | J17: 626608216 | K17: 1277.91 | L17: 24 | M17: 1537.86 | N17: 1.203418 | O17: =N17/'Read Me & Markers'!$B$8 -> 1.1872184 | P17: 53.25 | Q17: =P17/'Read Me & Markers'!$B$9 -> 0.88375189 | R17: 0.02833433 | S17: 69.77 | T17: 1.654353 | U17: 18317 | V17: 519 | W17: 77 | X17: 65 | Y17: 16196 | Z17: 1098 | AA17: =IF(U17>0,Y17/U17,0) -> 0.88420593 | AB17: =IF(Y17>0,Z17/Y17,0) -> 0.067794517 | AC17: Jun 1.21x ($1,273) | AD17: (from existing post) | AE17: (from existing post) | AF17: Say goodbye to tiredness! NAD+ levels drop with age, but our NMN Complex helps boost them for clean energy & focus. | AG17: SHOP_NOW / post CTA | AI17: 2241668536686089 | AJ17: https://www.facebook.com/1012373248616002_122115516417199246
A18: B. Strong performer | B18: 16 | C18: 120253373061420341 | D18: 8. NMN Testing Campaign (CBO) June 21 2026 | E18: 57. Mixed Batch | 15Aug 2026 | F18: ACTIVE | G18: 2026-08-15 | H18: NMN Complex | I18: Image | J18: img fb0b1b9f | K18: 1518.7 | L18: 24 | M18: 1823.34 | N18: 1.200593 | O18: =N18/'Read Me & Markers'!$B$8 -> 1.1844314 | P18: 63.28 | Q18: =P18/'Read Me & Markers'!$B$9 -> 1.0502126 | R18: 0.015121 | S18: 55.6 | T18: 1.931612 | U18: 27313 | V18: 413 | W18: 19 | X18: 52 | Y18: 0 | Z18: 0 | AA18: =IF(U18>0,Y18/U18,0) -> 0 | AB18: =IF(Y18>0,Z18/Y18,0) -> 0 | AC18: Aug 1.06x ($1,064) | Sep 1.05x ($310) | Oct* 2.56x ($145) | AD18: SUMMER SALE! 75% OFF TODAY ONLY! | AE18: Feeling more tired as you age? It's not "just aging." Your NAD+ levels naturally drop — the molecule your cells need for clean, steady energy. Our NMN Complex helps support those levels so you can feel energized, focused, and clear again. | AF18: Say goodbye to tiredness! NAD+ levels drop with age, but our NMN Complex helps boost them for clean energy & focus. | AG18: SHOP_NOW | AI18: 1069562665424660 | AJ18: https://www.facebook.com/1012373248616002_122136309597199246
A19: B. Strong performer | B19: - Video - Ad - 3 - Copy | C19: 120252553065040341 | D19: 9. NMN Scale Campaign (CBO) June 27 2026 | E19: 50. (98. May 26 USA 1-3 - Video Ad 3) | F19: ADSET_PAUSED | G19: 2026-07-18 | H19: NMN Complex | I19: Video (existing post) | J19: 709767483 | K19: 3496.14 | L19: 67 | M19: 4150.75 | N19: 1.187238 | O19: =N19/'Read Me & Markers'!$B$8 -> 1.1712562 | P19: 52.18 | Q19: =P19/'Read Me & Markers'!$B$9 -> 0.86599387 | R19: 0.06181885 | S19: 160.09 | T19: 1.295562 | U19: 21838 | V19: 1350 | W19: 39 | X19: 172 | Y19: 20195 | Z19: 5091 | AA19: =IF(U19>0,Y19/U19,0) -> 0.92476417 | AB19: =IF(Y19>0,Z19/Y19,0) -> 0.2520921 | AC19: Jul 1.34x ($2,274) | Aug 0.90x ($1,222) | AD19: (from existing post) | AE19: (from existing post) | AF19: Say goodbye to tiredness! NAD+ levels drop with age, but our NMN Complex helps boost them for clean energy & focus. | AG19: SHOP_NOW / post CTA | AI19: 2245320552903281 | AJ19: https://www.facebook.com/1012373248616002_122133831009199246
A20: B. Strong performer | B20: - Video - Ad - 1 | C20: 120249838080410341 | D20: 4. N2 Testing Campaign (CBO) Jan 27 2026 | E20: 128. June 7 USA 7-9 | F20: PAUSED | G20: 2026-06-07 | H20: NMN Complex | I20: Video | J20: 718294520 | K20: 1685.44 | L20: 38 | M20: 1987.32 | N20: 1.179111 | O20: =N20/'Read Me & Markers'!$B$8 -> 1.1632386 | P20: 44.35 | Q20: =P20/'Read Me & Markers'!$B$9 -> 0.736045 | R20: 0.05544971 | S20: 110.73 | T20: 1.40092 | U20: 15221 | V20: 844 | W20: 107 | X20: 92 | Y20: 14044 | Z20: 3383 | AA20: =IF(U20>0,Y20/U20,0) -> 0.92267262 | AB20: =IF(Y20>0,Z20/Y20,0) -> 0.24088579 | AC20: Jul 1.18x ($1,681) | AD20: SPRING SALE! 75% OFF TODAY ONLY! | AE20: Feeling more tired as you age? It's not "just aging." Your NAD+ levels naturally drop — the molecule your cells need for clean, steady energy. Our NMN Complex helps support those levels so you can feel energized, focused, and clear again. | AF20: Say goodbye to tiredness! NAD+ levels drop with age, but our NMN Complex helps boost them for clean energy & focus. | AG20: SHOP_NOW | AH20: 1330036105760479 | AI20: 3238111486379518 | AJ20: https://www.facebook.com/1012373248616002_122128721823199246
A21: B. Strong performer | B21: - Video - Ad - 1 - Copy | C21: 120252286003320341 | D21: 9. NMN Scale Campaign (CBO) June 27 2026 | E21: 39. (128. June 7 USA 7-9 - Video Ad 1) | F21: ADSET_PAUSED | G21: 2026-07-09 | H21: NMN Complex | I21: Video | J21: 742031353 | K21: 2257.36 | L21: 41 | M21: 2622.5 | N21: 1.161755 | O21: =N21/'Read Me & Markers'!$B$8 -> 1.1461162 | P21: 55.06 | Q21: =P21/'Read Me & Markers'!$B$9 -> 0.91379116 | R21: 0.04727866 | S21: 141.55 | T21: 1.231791 | U21: 15948 | V21: 754 | W21: 52 | X21: 82 | Y21: 14778 | Z21: 3242 | AA21: =IF(U21>0,Y21/U21,0) -> 0.92663657 | AB21: =IF(Y21>0,Z21/Y21,0) -> 0.21938016 | AC21: Aug 1.17x ($2,252) | AD21: SUMMER SALE! 75% OFF TODAY ONLY! | AE21: Feeling more tired as you age? It's not "just aging." Your NAD+ levels naturally drop — the molecule your cells need for clean, steady energy. Our NMN Complex helps support those levels so you can feel energized, focused, and clear again. | AF21: Say goodbye to tiredness! NAD+ levels drop with age, but our NMN Complex helps boost them for clean energy & focus. | AG21: SHOP_NOW | AH21: 2142589813137629 | AI21: 1005643872382237 | AJ21: https://www.facebook.com/1012373248616002_122132877891199246
A22: B. Strong performer | B22: - Video - Ad - 2 | C22: 120249493536790341 | D22: 7. N2 Testing Campaign (CBO) May 28 2026 | E22: 12. June 3 USA 13-15 | F22: CAMPAIGN_PAUSED | G22: 2026-06-03 | H22: NMN Complex | I22: Video | J22: 712467393 | K22: 4576.45 | L22: 76 | M22: 5227.4 | N22: 1.142239 | O22: =N22/'Read Me & Markers'!$B$8 -> 1.1268629 | P22: 60.22 | Q22: =P22/'Read Me & Markers'!$B$9 -> 0.99942796 | R22: 0.04478302 | S22: 111.38 | T22: 1.297921 | U22: 41087 | V22: 1840 | W22: 201 | X22: 154 | Y22: 38668 | Z22: 11343 | AA22: =IF(U22>0,Y22/U22,0) -> 0.94112493 | AB22: =IF(Y22>0,Z22/Y22,0) -> 0.29334333 | AC22: Jun 1.14x ($4,576) | AD22: SPRING SALE! 75% OFF TODAY ONLY! | AE22: Feeling more tired as you age? It's not "just aging." Your NAD+ levels naturally drop — the molecule your cells need for clean, steady energy. Our NMN Complex helps support those levels so you can feel energized, focused, and clear again. | AF22: Say goodbye to tiredness! NAD+ levels drop with age, but our NMN Complex helps boost them for clean energy & focus. | AG22: SHOP_NOW | AH22: 1032683339423824 | AI22: 1633646954417400 | AJ22: https://www.facebook.com/1012373248616002_122128343151199246
A23: B. Strong performer | B23: - Video - Ad -2 - Copy | C23: 120251695134020341 | D23: 9. NMN Scale Campaign (CBO) June 27 2026 | E23: 31. (11. Feb 6 USA 19-21 - Video Ad -2) | F23: ACTIVE | G23: 2026-06-27 | H23: NMN Complex | I23: Video (existing post) | J23: 626417952 | K23: 6943.02 | L23: 109 | M23: 7706.08 | N23: 1.109903 | O23: =N23/'Read Me & Markers'!$B$8 -> 1.0949622 | P23: 63.7 | Q23: =P23/'Read Me & Markers'!$B$9 -> 1.057183 | R23: 0.0262326 | S23: 92.22 | T23: 2.254199 | U23: 75288 | V23: 1975 | W23: 122 | X23: 279 | Y23: 61087 | Z23: 3073 | AA23: =IF(U23>0,Y23/U23,0) -> 0.81137764 | AB23: =IF(Y23>0,Z23/Y23,0) -> 0.050305302 | AC23: Jul 1.73x ($1,017) | Sep 1.06x ($3,885) | Oct* 0.89x ($2,039) | AD23: (from existing post) | AE23: (from existing post) | AF23: Say goodbye to tiredness! NAD+ levels drop with age, but our NMN Complex helps boost them for clean energy & focus. | AG23: SHOP_NOW / post CTA | AI23: 2990944634413848 | AJ23: https://www.facebook.com/1012373248616002_122131240551199246
A24: C. Scale workhorse | B24: - Video - Ad -2 - Copy | C24: 120251692693440341 | D24: 9. NMN Scale Campaign (CBO) June 27 2026 | E24: 5. (57. March 16 USA 4-6 - Video Ad -2) | F24: PAUSED | G24: 2026-06-27 | H24: NMN Complex | I24: Video (existing post) | J24: 626804201 | K24: 19526.1 | L24: 318 | M24: 21345.86 | N24: 1.093196 | O24: =N24/'Read Me & Markers'!$B$8 -> 1.0784801 | P24: 61.4 | Q24: =P24/'Read Me & Markers'!$B$9 -> 1.0190116 | R24: 0.02969702 | S24: 96.13 | T24: 2.511878 | U24: 203118 | V24: 6032 | W24: 321 | X24: 809 | Y24: 169219 | Z24: 9412 | AA24: =IF(U24>0,Y24/U24,0) -> 0.83310686 | AB24: =IF(Y24>0,Z24/Y24,0) -> 0.055620232 | AC24: Jun 1.42x ($304) | Jul 1.48x ($4,179) | Aug 1.17x ($5,251) | Sep 0.96x ($7,922) | Oct* 0.52x ($1,870) | AD24: (from existing post) | AE24: (from existing post) | AF24: Say goodbye to tiredness! NAD+ levels drop with age, but our NMN Complex helps boost them for clean energy & focus. | AG24: SHOP_NOW / post CTA | AI24: 1040744398420375 | AJ24: https://www.facebook.com/1012373248616002_122131612425199246
A25: C. Scale workhorse | B25: - Video - Ad - 1 - Copy 2 | C25: 120251694302990341 | D25: 9. NMN Scale Campaign (CBO) June 27 2026 | E25: 15. (5. Feb 28 (24. Feb 23 USA 10-12) - Video Ad 1 Copy) | F25: ACTIVE | G25: 2026-06-27 | H25: NMN Complex | I25: Video (existing post) | J25: 634374960 | K25: 66429.42 | L25: 1117 | M25: 66508.13 | N25: 1.001185 | O25: =N25/'Read Me & Markers'!$B$8 -> 0.98770772 | P25: 59.47 | Q25: =P25/'Read Me & Markers'!$B$9 -> 0.98698075 | R25: 0.05773769 | S25: 166.43 | T25: 2.108914 | U25: 399150 | V25: 23046 | W25: 1046 | X25: 2834 | Y25: 370957 | Z25: 80946 | AA25: =IF(U25>0,Y25/U25,0) -> 0.92936741 | AB25: =IF(Y25>0,Z25/Y25,0) -> 0.21820858 | AC25: Jul 1.28x ($23,680) | Aug 1.16x ($6,477) | Sep 0.86x ($25,481) | Oct* 0.62x ($10,794) | AD25: (from existing post) | AE25: (from existing post) | AF25: Say goodbye to tiredness! NAD+ levels drop with age, but our NMN Complex helps boost them for clean energy & focus. | AG25: SHOP_NOW / post CTA | AI25: 1626481615112414 | AJ25: https://www.facebook.com/1012373248616002_122131240665199246
A26: D. Promising (needs more spend) | B26: - Video - Ad - 3 | C26: 120248829172290341 | D26: 4. N2 Testing Campaign (CBO) Jan 27 2026 | E26: 110. May 27 USA 16-18 | F26: PAUSED | G26: 2026-05-27 | H26: NMN Complex | I26: Video (existing post) | J26: 709735887 | K26: 443.23 | L26: 12 | M26: 956.84 | N26: 2.158789 | O26: =N26/'Read Me & Markers'!$B$8 -> 2.1297288 | P26: 36.94 | Q26: =P26/'Read Me & Markers'!$B$9 -> 0.61306657 | R26: 0.06314168 | S26: 113.77 | T26: 1.337912 | U26: 3896 | V26: 246 | W26: 46 | X26: 24 | Y26: 3274 | Z26: 602 | AA26: =IF(U26>0,Y26/U26,0) -> 0.84034908 | AB26: =IF(Y26>0,Z26/Y26,0) -> 0.18387294 | AD26: (from existing post) | AE26: (from existing post) | AF26: Say goodbye to tiredness! NAD+ levels drop with age, but our NMN Complex helps boost them for clean energy & focus. | AG26: SHOP_NOW / post CTA | AI26: 1480777233047903 | AJ26: https://www.facebook.com/1012373248616002_122127589425199246
A27: D. Promising (needs more spend) | B27: 14. 20260923_Only4hrsLeft_V1 | C27: 120254362729110341 | D27: 8. NMN Testing Campaign (CBO) June 21 2026 | E27: 72__Broad_USA_Creative_testing | F27: ACTIVE | G27: 2026-10-08 | H27: NMN Complex | I27: Video | J27: 841545460 | K27: 578.29 | L27: 18 | M27: 1237.35 | N27: 2.13967 | O27: =N27/'Read Me & Markers'!$B$8 -> 2.1108672 | P27: 32.13 | Q27: =P27/'Read Me & Markers'!$B$9 -> 0.53323846 | R27: 0.02206991 | S27: 79.27 | T27: 1.448858 | U27: 7295 | V27: 161 | W27: 3 | X27: 31 | Y27: 6494 | Z27: 317 | AA27: =IF(U27>0,Y27/U27,0) -> 0.89019877 | AB27: =IF(Y27>0,Z27/Y27,0) -> 0.04881429 | AD27: Support Energy Without More Coffee | AE27: Feeling more tired as you age? It's not "just aging." Your NAD+ levels naturally drop — the molecule your cells need for clean, steady energy. Our NMN Complex helps support those levels so you can feel energized, focused, and clear again. | AF27: Say goodbye to tiredness! NAD+ levels drop with age, but our NMN Complex helps boost them for clean energy & focus. | AG27: SHOP_NOW | AH27: 1525110046048907 | AI27: 884411534757584 | AJ27: https://www.facebook.com/1012373248616002_122142749583199246
A28: D. Promising (needs more spend) | B28: - Video - Ad - 3 | C28: 120245594344380341 | D28: 4. N2 Testing Campaign (CBO) Jan 27 2026 | E28: 75. March 24 USA 16-18 | F28: PAUSED | G28: 2026-04-08 | H28: NMN Complex | I28: Video (existing post) | J28: 626804201 | K28: 786.55 | L28: 23 | M28: 1545.42 | N28: 1.964808 | O28: =N28/'Read Me & Markers'!$B$8 -> 1.9383591 | P28: 34.2 | Q28: =P28/'Read Me & Markers'!$B$9 -> 0.56759276 | R28: 0.02936418 | S28: 63.63 | T28: 1.773092 | U28: 12362 | V28: 363 | W28: 72 | X28: 73 | Y28: 9722 | Z28: 778 | AA28: =IF(U28>0,Y28/U28,0) -> 0.78644232 | AB28: =IF(Y28>0,Z28/Y28,0) -> 0.080024686 | AD28: (from existing post) | AE28: (from existing post) | AF28: Say goodbye to tiredness! NAD+ levels drop with age, but our NMN Complex helps boost them for clean energy & focus. | AG28: SHOP_NOW / post CTA | AI28: 4235728330090163 | AJ28: https://www.facebook.com/1012373248616002_122121141321199246
A29: D. Promising (needs more spend) | B29: - Video - Ad - 1 - Copy 2 | C29: 120251694341740341 | D29: 9. NMN Scale Campaign (CBO) June 27 2026 | E29: 20. (6. Mar 1 (14. Feb 17 USA 4-6) - Video Ad 1 Copy) | F29: PAUSED | G29: 2026-06-27 | H29: NMN Complex | I29: Video (existing post) | J29: 629474851 | K29: 321.43 | L29: 11 | M29: 582.08 | N29: 1.810908 | O29: =N29/'Read Me & Markers'!$B$8 -> 1.7865308 | P29: 29.22 | Q29: =P29/'Read Me & Markers'!$B$9 -> 0.48494329 | R29: 0.02764771 | S29: 71.67 | T29: 1.420653 | U29: 4485 | V29: 124 | W29: 14 | X29: 19 | Y29: 3678 | Z29: 229 | AA29: =IF(U29>0,Y29/U29,0) -> 0.82006689 | AB29: =IF(Y29>0,Z29/Y29,0) -> 0.062262099 | AD29: (from existing post) | AE29: (from existing post) | AF29: Say goodbye to tiredness! NAD+ levels drop with age, but our NMN Complex helps boost them for clean energy & focus. | AG29: SHOP_NOW / post CTA | AI29: 2190818785033212 | AJ29: https://www.facebook.com/1012373248616002_122131240497199246
A30: D. Promising (needs more spend) | B30: - Video - Ad - 2 - Copy | C30: 120251692908690341 | D30: 9. NMN Scale Campaign (CBO) June 27 2026 | E30: 7. (72. March 24 USA 7-9 - Video Ad 2) | F30: PAUSED | G30: 2026-06-27 | H30: NMN Complex | I30: Video (existing post) | J30: 627853673 | K30: 924.7 | L30: 24 | M30: 1662.03 | N30: 1.797372 | O30: =N30/'Read Me & Markers'!$B$8 -> 1.773177 | P30: 38.53 | Q30: =P30/'Read Me & Markers'!$B$9 -> 0.63945465 | R30: 0.03450468 | S30: 83.96 | T30: 1.509664 | U30: 11013 | V30: 380 | W30: 68 | X30: 57 | Y30: 9585 | Z30: 479 | AA30: =IF(U30>0,Y30/U30,0) -> 0.87033506 | AB30: =IF(Y30>0,Z30/Y30,0) -> 0.049973918 | AD30: (from existing post) | AE30: (from existing post) | AF30: Say goodbye to tiredness! NAD+ levels drop with age, but our NMN Complex helps boost them for clean energy & focus. | AG30: SHOP_NOW / post CTA | AI30: 1337341958526187 | AJ30: https://www.facebook.com/1012373248616002_122131240851199246
A31: D. Promising (needs more spend) | B31: - Video - Ad - 8 | C31: 120246424579260341 | D31: 4. N2 Testing Campaign (CBO) Jan 27 2026 | E31: 86. April 1 USA 7-9 | F31: PAUSED | G31: 2026-04-24 | H31: NMN Complex | I31: Video (existing post) | J31: 679672087 | K31: 376.28 | L31: 10 | M31: 657.97 | N31: 1.748618 | O31: =N31/'Read Me & Markers'!$B$8 -> 1.7250793 | P31: 37.63 | Q31: =P31/'Read Me & Markers'!$B$9 -> 0.624518 | R31: 0.02171624 | S31: 49.52 | T31: 1.572759 | U31: 7598 | V31: 165 | W31: 33 | X31: 30 | Y31: 6013 | Z31: 358 | AA31: =IF(U31>0,Y31/U31,0) -> 0.79139247 | AB31: =IF(Y31>0,Z31/Y31,0) -> 0.059537668 | AD31: (from existing post) | AE31: (from existing post) | AF31: Say goodbye to tiredness! NAD+ levels drop with age, but our NMN Complex helps boost them for clean energy & focus. | AG31: SHOP_NOW / post CTA | AI31: 2063997697491844 | AJ31: https://www.facebook.com/1012373248616002_122123470965199246
A32: D. Promising (needs more spend) | B32: 880922768391820_brand | C32: 120252620424510341 | D32: 8. NMN Testing Campaign (CBO) June 21 2026 | E32: 30. Static Recreations F | 21Jul | F32: ACTIVE | G32: 2026-07-22 | H32: NMN Complex | I32: Image | J32: img 83e300fa | K32: 434.6 | L32: 10 | M32: 743.2 | N32: 1.710078 | O32: =N32/'Read Me & Markers'!$B$8 -> 1.6870581 | P32: 43.46 | Q32: =P32/'Read Me & Markers'!$B$9 -> 0.72127431 | R32: 0.0193248 | S32: 50.59 | T32: 1.596951 | U32: 8590 | V32: 166 | W32: 8 | X32: 21 | Y32: 0 | Z32: 0 | AA32: =IF(U32>0,Y32/U32,0) -> 0 | AB32: =IF(Y32>0,Z32/Y32,0) -> 0 | AD32: SPRING SALE! 75% OFF TODAY ONLY! | AE32: Feeling more tired as you age? It's not "just aging." Your NAD+ levels naturally drop — the molecule your cells need for clean, steady energy. Our NMN Complex helps support those levels so you can feel energized, focused, and clear again. | AF32: Say goodbye to tiredness! NAD+ levels drop with age, but our NMN Complex helps boost them for clean energy & focus. | AG32: SHOP_NOW | AI32: 1554823429427068 | AJ32: https://www.facebook.com/1012373248616002_122134114779199246
A33: D. Promising (needs more spend) | B33: - Video - Ad - 14 | C33: 120245650660660341 | D33: 1. Testing Campaign (CBO) Campaign Nov 8 2025 | E33: 77. March 24 USA - 13-15 | F33: PAUSED | G33: 2026-04-09 | H33: Astaxanthin | I33: Video (existing post) | J33: 669990045 | K33: 333.22 | L33: 8 | M33: 534.19 | N33: 1.603115 | O33: =N33/'Read Me & Markers'!$B$8 -> 1.5815349 | P33: 41.65 | Q33: =P33/'Read Me & Markers'!$B$9 -> 0.69123505 | R33: 0.03394834 | S33: 49.18 | T33: 1.377593 | U33: 6775 | V33: 230 | W33: 23 | X33: 18 | Y33: 5932 | Z33: 407 | AA33: =IF(U33>0,Y33/U33,0) -> 0.87557196 | AB33: =IF(Y33>0,Z33/Y33,0) -> 0.068610924 | AD33: (from existing post) | AE33: (from existing post) | AF33: ✨ Protect Your Skin from Within! ✨ Boost your natural glow, energy, and recovery with 12mg of pure, algae-sourced Astaxanthin — one of nature's most powerful antioxidants. 💧 Reduce fine lines & improve skin texture ⚡ Fight fatigue and support cellular energy 🛡️ Defend against UV damage and environmental stress. Just one easy-to-take softgel a day with food keeps your skin, body, and energy in top form — naturally. | AG33: SHOP_NOW / post CTA | AI33: 978935291753416 | AJ33: https://www.facebook.com/1012373248616002_122121416211199246
A34: D. Promising (needs more spend) | B34: - Video - Ad - 3 | C34: 120249493555990341 | D34: 7. N2 Testing Campaign (CBO) May 28 2026 | E34: 14. June 3 USA 19-21 | F34: CAMPAIGN_PAUSED | G34: 2026-06-03 | H34: NMN Complex | I34: Video | J34: 711679836 | K34: 672.95 | L34: 17 | M34: 1031.71 | N34: 1.533115 | O34: =N34/'Read Me & Markers'!$B$8 -> 1.5124772 | P34: 39.59 | Q34: =P34/'Read Me & Markers'!$B$9 -> 0.65704671 | R34: 0.04424635 | S34: 109.07 | T34: 1.176358 | U34: 6170 | V34: 273 | W34: 45 | X34: 37 | Y34: 5724 | Z34: 1049 | AA34: =IF(U34>0,Y34/U34,0) -> 0.92771475 | AB34: =IF(Y34>0,Z34/Y34,0) -> 0.18326345 | AD34: SPRING SALE! 75% OFF TODAY ONLY! | AE34: Feeling more tired as you age? It's not "just aging." Your NAD+ levels naturally drop — the molecule your cells need for clean, steady energy. Our NMN Complex helps support those levels so you can feel energized, focused, and clear again. | AF34: Say goodbye to tiredness! NAD+ levels drop with age, but our NMN Complex helps boost them for clean energy & focus. | AG34: SHOP_NOW | AH34: 996309953144867 | AI34: 1035978388992947 | AJ34: https://www.facebook.com/1012373248616002_122128343433199246
A35: D. Promising (needs more spend) | B35: BOF - Video - Ad - 8 | C35: 120241639407520341 | D35: 1. Testing Campaign (CBO) Campaign Nov 8 2025 | E35: Nov 28 USA BOF 7-9 | F35: PAUSED | G35: 2026-01-08 | H35: Astaxanthin | I35: Video (existing post) | J35: 611765502 | K35: 264.3 | L35: 7 | M35: 404.53 | N35: 1.530571 | O35: =N35/'Read Me & Markers'!$B$8 -> 1.5099675 | P35: 37.76 | Q35: =P35/'Read Me & Markers'!$B$9 -> 0.62667552 | R35: 0.04563013 | S35: 63.81 | T35: 1.314503 | U35: 4142 | V35: 189 | W35: 22 | X35: 20 | Y35: 3711 | Z35: 352 | AA35: =IF(U35>0,Y35/U35,0) -> 0.89594399 | AB35: =IF(Y35>0,Z35/Y35,0) -> 0.094853139 | AD35: (from existing post) | AE35: (from existing post) | AF35: ✨ Protect Your Skin from Within! ✨ Boost your natural glow, energy, and recovery with 12mg of pure, algae-sourced Astaxanthin — one of nature's most powerful antioxidants. 💧 Reduce fine lines & improve skin texture ⚡ Fight fatigue and support cellular energy 🛡️ Defend against UV damage and environmental stress. Just one easy-to-take softgel a day with food keeps your skin, body, and energy in top form — naturally. | AG35: SHOP_NOW / post CTA | AI35: 875948311486626 | AJ35: https://www.facebook.com/1012373248616002_122102207457199246
A36: D. Promising (needs more spend) | B36: - Video - Ad - 3 | C36: 120248163157430341 | D36: 4. N2 Testing Campaign (CBO) Jan 27 2026 | E36: 91. May 19 USA 1-3 | F36: PAUSED | G36: 2026-05-19 | H36: NMN Complex | I36: Video (existing post) | J36: 678400989 | K36: 317.41 | L36: 9 | M36: 474.14 | N36: 1.493778 | O36: =N36/'Read Me & Markers'!$B$8 -> 1.4736698 | P36: 35.27 | Q36: =P36/'Read Me & Markers'!$B$9 -> 0.58535078 | R36: 0.03871829 | S36: 105.94 | T36: 1.113755 | U36: 2996 | V36: 116 | W36: 16 | X36: 14 | Y36: 2772 | Z36: 526 | AA36: =IF(U36>0,Y36/U36,0) -> 0.92523364 | AB36: =IF(Y36>0,Z36/Y36,0) -> 0.18975469 | AD36: (from existing post) | AE36: (from existing post) | AF36: Say goodbye to tiredness! NAD+ levels drop with age, but our NMN Complex helps boost them for clean energy & focus. | AG36: SHOP_NOW / post CTA | AI36: 991483349965005 | AJ36: https://www.facebook.com/1012373248616002_122126657445199246
A37: D. Promising (needs more spend) | B37: - Video - Ad - 3 | C37: 120245907039620341 | D37: 4. N2 Testing Campaign (CBO) Jan 27 2026 | E37: 77. March 28 USA 1-3 | F37: PAUSED | G37: 2026-04-16 | H37: NMN Complex | I37: Video | J37: 673475914 | K37: 324.46 | L37: 6 | M37: 477.72 | N37: 1.472354 | O37: =N37/'Read Me & Markers'!$B$8 -> 1.4525342 | P37: 54.08 | Q37: =P37/'Read Me & Markers'!$B$9 -> 0.8975268 | R37: 0.01960512 | S37: 45.11 | T37: 1.592207 | U37: 7192 | V37: 141 | W37: 19 | X37: 25 | Y37: 6007 | Z37: 586 | AA37: =IF(U37>0,Y37/U37,0) -> 0.83523359 | AB37: =IF(Y37>0,Z37/Y37,0) -> 0.097552855 | AD37: FLASH SALE! 75% OFF TODAY ONLY! | AE37: Feeling more tired as you age? It's not "just aging." Your NAD+ levels naturally drop — the molecule your cells need for clean, steady energy. Our NMN Complex helps support those levels so you can feel energized, focused, and clear again. | AF37: Say goodbye to tiredness! NAD+ levels drop with age, but our NMN Complex helps boost them for clean energy & focus. | AG37: SHOP_NOW | AH37: 1525071269047331 | AI37: 3803824336593159 | AJ37: https://www.facebook.com/1012373248616002_122122408935199246
A38: D. Promising (needs more spend) | B38: - Video - Ad - 1 | C38: 120242733176410341 | D38: 4. N2 Testing Campaign (CBO) Jan 27 2026 | E38: 12. Feb 6 USA 16-18 | F38: PAUSED | G38: 2026-02-06 | H38: NMN Complex | I38: Video (existing post) | J38: 626804201 | K38: 271.98 | L38: 6 | M38: 392.52 | N38: 1.443194 | O38: =N38/'Read Me & Markers'!$B$8 -> 1.4237667 | P38: 45.33 | Q38: =P38/'Read Me & Markers'!$B$9 -> 0.75230936 | R38: 0.03456341 | S38: 70.68 | T38: 1.168185 | U38: 3848 | V38: 133 | W38: 27 | X38: 18 | Y38: 3322 | Z38: 146 | AA38: =IF(U38>0,Y38/U38,0) -> 0.86330561 | AB38: =IF(Y38>0,Z38/Y38,0) -> 0.043949428 | AD38: (from existing post) | AE38: (from existing post) | AF38: Say goodbye to tiredness! NAD+ levels drop with age, but our NMN Complex helps boost them for clean energy & focus. | AG38: SHOP_NOW / post CTA | AI38: 907928314975420 | AJ38: https://www.facebook.com/1012373248616002_122111830383199246
A39: D. Promising (needs more spend) | B39: 1. 3 Bottle Offer - 1 (P2) | C39: 120251994279470341 | D39: 8. NMN Testing Campaign (CBO) June 21 2026 | E39: 1. 3 Bottle Offer | 30Jun | F39: ACTIVE | G39: 2026-07-02 | H39: NMN Complex | I39: Image | J39: img be567392 | K39: 324.46 | L39: 8 | M39: 462.17 | N39: 1.424428 | O39: =N39/'Read Me & Markers'!$B$8 -> 1.4052533 | P39: 40.56 | Q39: =P39/'Read Me & Markers'!$B$9 -> 0.6731451 | R39: 0.02587295 | S39: 68.25 | T39: 1.644414 | U39: 4754 | V39: 123 | W39: 18 | X39: 19 | Y39: 0 | Z39: 0 | AA39: =IF(U39>0,Y39/U39,0) -> 0 | AB39: =IF(Y39>0,Z39/Y39,0) -> 0 | AD39: SUMMER SALE! 75% OFF TODAY ONLY! | AE39: I used to think the afternoon crash was just part of getting older. By 58, my mornings started fine — coffee, a short walk, a little energy in the tank. But by 2 or 3 o'clock, it was like someone pulled the plug. Foggy. Heavy. Reaching for another coffee I knew I'd regret. A friend who works in longevity research finally explained it to me... it's a molecule called NAD+... after 50 your levels can drop to a fraction of what they were in your 30s. NMN is a building block your body uses to help make more NAD+. So I started taking an NMN Complex every morning... I won't promise you miracles. But my afternoons feel steadier now... 👉 Our NMN Complex is 75% off today only. | AF39: The afternoon crash isn't a character flaw — it's chemistry. After 50, your cells' NAD+ levels quietly fall... Our NMN Complex helps support healthy NAD+... 75% off today only. | AG39: SHOP_NOW | AI39: 4752397118328029 | AJ39: https://www.facebook.com/1012373248616002_122131846503199246
A40: D. Promising (needs more spend) | B40: BOF - Video - Ad - 3 | C40: 120241948148610341 | D40: 2. Scaling Campaign (CBO) Jan 17 2026 | E40: 3. Jan 17 ( Dec 7 USA BOF - 4-6 ) | F40: PAUSED | G40: 2026-01-17 | H40: Astaxanthin | I40: Video (existing post) | J40: 613625533 | K40: 373.28 | L40: 8 | M40: 523.67 | N40: 1.402888 | O40: =N40/'Read Me & Markers'!$B$8 -> 1.3840033 | P40: 46.66 | Q40: =P40/'Read Me & Markers'!$B$9 -> 0.77438241 | R40: 0.01839254 | S40: 31.35 | T40: 1.695912 | U40: 11907 | V40: 219 | W40: 26 | X40: 20 | Y40: 7003 | Z40: 897 | AA40: =IF(U40>0,Y40/U40,0) -> 0.58814143 | AB40: =IF(Y40>0,Z40/Y40,0) -> 0.12808796 | AD40: (from existing post) | AE40: (from existing post) | AF40: ✨ Protect Your Skin from Within! ✨ Boost your natural glow, energy, and recovery with 12mg of pure, algae-sourced Astaxanthin — one of nature's most powerful antioxidants. 💧 Reduce fine lines & improve skin texture ⚡ Fight fatigue and support cellular energy 🛡️ Defend against UV damage and environmental stress. Just one easy-to-take softgel a day with food keeps your skin, body, and energy in top form — naturally. | AG40: SHOP_NOW / post CTA | AI40: 25986449060978676 | AJ40: https://www.facebook.com/1012373248616002_122102166711199246
...

Sheet Monthly Trend
A1: Ad name | B1: Ad ID | C1: Tier | D1: Apr* spend | E1: Apr* ROAS | F1: May spend | G1: May ROAS | H1: Jun spend | I1: Jun ROAS | J1: Jul spend | K1: Jul ROAS | L1: Aug spend | M1: Aug ROAS | N1: Sep spend | O1: Sep ROAS | P1: Oct* spend | Q1: Oct* ROAS
A2: - Video - Ad - 1 - Copy | B2: 120243619709580341 | C2: A. Proven winner | D2: 747.15 | E2: 3.236 | F2: 1654.46 | G2: 1.55
A3: - Video - Ad -2 | B3: 120244413721500341 | C3: A. Proven winner | F3: 0.56 | H3: 1009.8 | I3: 2.251 | J3: 148.99 | K3: 0.845
A4: 19 | B4: 120253373064280341 | C4: A. Proven winner | L4: 109.63 | M4: 2.061 | N4: 1023.91 | O4: 1.714 | P4: 276.27 | Q4: 1.143
A5: - Video - Ad - 1 | B5: 120243390597510341 | C5: A. Proven winner | D5: 2952.05 | E5: 1.411 | F5: 3620.37 | G5: 1.742
A6: - Video - Ad - 2 | B6: 120250187515990341 | C6: A. Proven winner | H6: 1403.37 | I6: 1.665 | J6: 89.86 | K6: 0.445
A7: - Video - Ad -2 | B7: 120242733176260341 | C7: A. Proven winner | D7: 179.33 | E7: 3.7 | F7: 1524.63 | G7: 1.273
A8: - Video - Ad - 1 - Copy | B8: 120243669805030341 | C8: A. Proven winner | D8: 12014.6 | E8: 1.78 | F8: 24327.72 | G8: 1.339
A9: - Video - Ad -12 | B9: 120245650660800341 | C9: A. Proven winner | D9: 164.8 | E9: 0.703 | F9: 1035.2 | G9: 1.592
A10: - Video - Ad - 1 | B10: 120243675534840341 | C10: A. Proven winner | D10: 5.51 | F10: 1.12 | H10: 6690.69 | I10: 1.417 | J10: 881.28 | K10: 1.252
A11: - Video - Ad - 3 | B11: 120242308889180341 | C11: A. Proven winner | D11: 2466.2 | E11: 1.453 | F11: 14014.65 | G11: 1.378
A12: - Video - Ad - 1 | B12: 120242733176430341 | C12: A. Proven winner | D12: 2364.15 | E12: 1.465 | F12: 1696.52 | G12: 1.256
A13: - Video - Ad - 1 | B13: 120243701969760341 | C13: A. Proven winner | D13: 1966.51 | E13: 1.395 | F13: 688.28 | G13: 1.234
A14: - Video - Ad -2 - Copy | B14: 120246199037900341 | C14: A. Proven winner | D14: 46.4 | E14: 1.723 | F14: 975.23 | G14: 1.323
A15: - Video - Ad - 1 - Copy | B15: 120243160670300341 | C15: B. Strong performer | D15: 1008.93 | E15: 1.729 | F15: 12530.31 | G15: 1.179
A16: - Video - Ad - 2 | B16: 120249839070250341 | C16: B. Strong performer | H16: 1757.8 | I16: 1.22
A17: - Video - Ad -2 | B17: 120243701969710341 | C17: B. Strong performer | D17: 3.41 | F17: 1.9 | H17: 1272.6 | I17: 1.208
A18: 16 | B18: 120253373061420341 | C18: B. Strong performer | L18: 1064 | M18: 1.058 | N18: 309.84 | O18: 1.052 | P18: 144.86 | Q18: 2.564
A19: - Video - Ad - 3 - Copy | B19: 120252553065040341 | C19: B. Strong performer | J19: 2274.15 | K19: 1.345 | L19: 1221.99 | M19: 0.895
A20: - Video - Ad - 1 | B20: 120249838080410341 | C20: B. Strong performer | H20: 3.99 | J20: 1681.45 | K20: 1.182
A21: - Video - Ad - 1 - Copy | B21: 120252286003320341 | C21: B. Strong performer | J21: 5.78 | L21: 2251.58 | M21: 1.165
A22: - Video - Ad - 2 | B22: 120249493536790341 | C22: B. Strong performer | H22: 4576.45 | I22: 1.142
A23: - Video - Ad -2 - Copy | B23: 120251695134020341 | C23: B. Strong performer | J23: 1016.94 | K23: 1.726 | L23: 2.64 | N23: 3885.06 | O23: 1.062 | P23: 2038.53 | Q23: 0.894
A24: - Video - Ad -2 - Copy | B24: 120251692693440341 | C24: C. Scale workhorse | H24: 304.33 | I24: 1.419 | J24: 4178.92 | K24: 1.478 | L24: 5251.24 | M24: 1.17 | N24: 7921.93 | O24: 0.961 | P24: 1869.68 | Q24: 0.522
A25: - Video - Ad - 1 - Copy 2 | B25: 120251694302990341 | C25: C. Scale workhorse | J25: 23680.48 | K25: 1.285 | L25: 6477.26 | M25: 1.156 | N25: 25480.67 | O25: 0.86 | P25: 10793.8 | Q25: 0.619
A27: * Apr = 16–30 Apr; Oct = 1–16 Oct. Green ≥1.30x, yellow 1.00–1.29x, red <1.00x. Source: Meta Ads, monthly breakdown.

Sheet Creative Concepts
A1: Visual ID | B1: Product | C1: Format | D1: Headline(s) | E1: # winning ads | F1: Amount spent ($) | G1: Purchases | H1: Purchase value ($) | I1: Purchase ROAS | J1: Cost per purchase ($) | K1: Best tier | L1: Ad IDs
A2: 634374960 | B2: NMN Complex | C2: Video (existing post) | D2: (existing post) | E2: 3 | F2: 109344.16 | G2: 2146 | H2: 130955.1 | I2: =IF(F2>0,H2/F2,0) -> 1.1976415 | J2: =IF(G2>0,F2/G2,0) -> 50.952544 | K2: A. Proven winner | L2: 120243390597510341, 120243669805030341, 120251694302990341
A3: 626804201 | B3: NMN Complex | C3: Video (existing post) | D3: (existing post) | E3: 5 | F3: 35283.22 | G3: 643 | H3: 42196.96 | I3: =IF(F3>0,H3/F3,0) -> 1.1959498 | J3: =IF(G3>0,F3/G3,0) -> 54.872815 | K3: A. Proven winner | L3: 120244413721500341, 120243160670300341, 120251692693440341, 120245594344380341, 120242733176410341
A4: 623055237 | B4: NMN Complex | C4: Video | D4: NEW YEAR FLASH SALE! 75% OFF TODAY ONLY! | E4: 1 | F4: 16480.85 | G4: 395 | H4: 22893.89 | I4: =IF(F4>0,H4/F4,0) -> 1.3891207 | J4: =IF(G4>0,F4/G4,0) -> 41.723671 | K4: A. Proven winner | L4: 120242308889180341
A5: 626417952 | B5: NMN Complex | C5: Video (existing post) | D5: (existing post) | E5: 4 | F5: 12323.4 | G5: 225 | H5: 15273.36 | I5: =IF(F5>0,H5/F5,0) -> 1.2393787 | J5: =IF(G5>0,F5/G5,0) -> 54.770667 | K5: A. Proven winner | L5: 120242733176260341, 120243701969760341, 120246199037900341, 120251695134020341
A6: 627853673 | B6: NMN Complex | C6: Video (existing post) | D6: (existing post) | E6: 2 | F6: 8503.3 | G6: 181 | H6: 12245.78 | I6: =IF(F6>0,H6/F6,0) -> 1.4401209 | J6: =IF(G6>0,F6/G6,0) -> 46.979558 | K6: A. Proven winner | L6: 120243675534840341, 120251692908690341
A7: 712467393 | B7: NMN Complex | C7: Video | D7: SPRING SALE! 75% OFF TODAY ONLY! | E7: 1 | F7: 4576.45 | G7: 76 | H7: 5227.4 | I7: =IF(F7>0,H7/F7,0) -> 1.1422391 | J7: =IF(G7>0,F7/G7,0) -> 60.216447 | K7: B. Strong performer | L7: 120249493536790341
A8: 626826360 | B8: NMN Complex | C8: Video (existing post) | D8: (existing post) | E8: 1 | F8: 4060.67 | G8: 86 | H8: 5594.95 | I8: =IF(F8>0,H8/F8,0) -> 1.3778391 | J8: =IF(G8>0,F8/G8,0) -> 47.217093 | K8: A. Proven winner | L8: 120242733176430341
A9: 709767483 | B9: NMN Complex | C9: Video (existing post) | D9: (existing post) | E9: 1 | F9: 3496.14 | G9: 67 | H9: 4150.75 | I9: =IF(F9>0,H9/F9,0) -> 1.1872379 | J9: =IF(G9>0,F9/G9,0) -> 52.181194 | K9: B. Strong performer | L9: 120252553065040341
A10: 632447272 | B10: NMN Complex | C10: Video (existing post) | D10: (existing post) | E10: 1 | F10: 2401.61 | G10: 71 | H10: 4981.57 | I10: =IF(F10>0,H10/F10,0) -> 2.0742627 | J10: =IF(G10>0,F10/G10,0) -> 33.825493 | K10: A. Proven winner | L10: 120243619709580341
A11: 742031353 | B11: NMN Complex | C11: Video | D11: SUMMER SALE! 75% OFF TODAY ONLY! | E11: 1 | F11: 2257.36 | G11: 41 | H11: 2622.5 | I11: =IF(F11>0,H11/F11,0) -> 1.1617553 | J11: =IF(G11>0,F11/G11,0) -> 55.057561 | K11: B. Strong performer | L11: 120252286003320341
A12: 712703739 | B12: NMN Complex | C12: Video | D12: SPRING SALE! 75% OFF TODAY ONLY! | E12: 1 | F12: 1757.8 | G12: 29 | H12: 2143.87 | I12: =IF(F12>0,H12/F12,0) -> 1.2196325 | J12: =IF(G12>0,F12/G12,0) -> 60.613793 | K12: B. Strong performer | L12: 120249839070250341
A13: 718294520 | B13: NMN Complex | C13: Video | D13: SPRING SALE! 75% OFF TODAY ONLY! | E13: 1 | F13: 1685.44 | G13: 38 | H13: 1987.32 | I13: =IF(F13>0,H13/F13,0) -> 1.1791105 | J13: =IF(G13>0,F13/G13,0) -> 44.353684 | K13: B. Strong performer | L13: 120249838080410341
... A33: 611765502 | B33: Astaxanthin | C33: Video (existing post) | D33: (existing post) | E33: 1 | F33: 264.3 | G33: 7 | H33: 404.53 | I33: =IF(F33>0,H33/F33,0) -> 1.5305713 | J33: =IF(G33>0,F33/G33,0) -> 37.757143 | K33: D. Promising (needs more spend) | L33: 120241639407520341
A35: Visual ID = thumbnail/image identifier from Meta; ads sharing it use the same visual asset. Sums cover qualifying ads only.

Sheet All Ads 6mo
A1: Ad ID | B1: Tier (formula) | C1: Ad name | D1: Campaign | E1: Ad set | F1: Status | G1: Created | H1: Creative ID | I1: Amount spent ($) | J1: Purchases | K1: Purchase value ($) | L1: Purchase ROAS | M1: Cost per purchase ($) | N1: CTR (link) | O1: CPM ($) | P1: Frequency | Q1: Impressions | R1: Link clicks | S1: Adds to cart | T1: Checkouts initiated | U1: Video plays | V1: ThruPlays
A2: 120251694302990341 | B2: =IF(AND(I2>='Read Me & Markers'!$B$18,J2>='Read Me & Markers'!$B$19,L2>='Read Me & Markers'!$B$20),"A. Proven winner",IF(AND(I2>='Read Me & Markers'!$B$18,J2>='Read Me & Markers'!$B$19,L2>='Read Me & Markers'!$B$21),"B. Strong performer",IF(AND(I2>='Read Me & Markers'!$B$22,L2>='Read Me & Markers'!$B$23),"C. Scale workhorse",IF(AND(I2>='Read Me & Markers'!$B$24,I2<'Read Me & Markers'!$B$18,J2>='Read Me & Markers'!$B$25,L2>='Read Me & Markers'!$B$26),"D. Promising (needs more spend)","")))) -> C. Scale workhorse | C2: - Video - Ad - 1 - Copy 2 | D2: 9. NMN Scale Campaign (CBO) June 27 2026 | E2: 15. (5. Feb 28 (24. Feb 23 USA 10-12) - Video Ad 1 Copy) | F2: ACTIVE | G2: 2026-06-27 | H2: 1626481615112414 | I2: 66429.42 | J2: 1117 | K2: 66508.13 | L2: 1.001185 | M2: 59.47 | N2: 0.05773769 | O2: 166.43 | P2: 2.108914 | Q2: 399150 | R2: 23046 | S2: 1046 | T2: 2834 | U2: 370957 | V2: 80946
A3: 120251699320370341 | B3: =IF(AND(I3>='Read Me & Markers'!$B$18,J3>='Read Me & Markers'!$B$19,L3>='Read Me & Markers'!$B$20),"A. Proven winner",IF(AND(I3>='Read Me & Markers'!$B$18,J3>='Read Me & Markers'!$B$19,L3>='Read Me & Markers'!$B$21),"B. Strong performer",IF(AND(I3>='Read Me & Markers'!$B$22,L3>='Read Me & Markers'!$B$23),"C. Scale workhorse",IF(AND(I3>='Read Me & Markers'!$B$24,I3<'Read Me & Markers'!$B$18,J3>='Read Me & Markers'!$B$25,L3>='Read Me & Markers'!$B$26),"D. Promising (needs more spend)","")))) | C3: - Video - Ad - 3 | D3: 9. NMN Scale Campaign (CBO) June 27 2026 | E3: 22 (Jan 27 USA 7-9 - Video Ad 3) | F3: PAUSED | G3: 2026-06-27 | H3: 1056616350387972 | I3: 48771.81 | J3: 689 | K3: 38827.43 | L3: 0.796104 | M3: 70.79 | N3: 0.08679342 | O3: 234.87 | P3: 1.445444 | Q3: 207654 | R3: 18023 | S3: 537 | T3: 1705 | U3: 186803 | V3: 70027
A4: 120243669805030341 | B4: =IF(AND(I4>='Read Me & Markers'!$B$18,J4>='Read Me & Markers'!$B$19,L4>='Read Me & Markers'!$B$20),"A. Proven winner",IF(AND(I4>='Read Me & Markers'!$B$18,J4>='Read Me & Markers'!$B$19,L4>='Read Me & Markers'!$B$21),"B. Strong performer",IF(AND(I4>='Read Me & Markers'!$B$22,L4>='Read Me & Markers'!$B$23),"C. Scale workhorse",IF(AND(I4>='Read Me & Markers'!$B$24,I4<'Read Me & Markers'!$B$18,J4>='Read Me & Markers'!$B$25,L4>='Read Me & Markers'!$B$26),"D. Promising (needs more spend)","")))) -> A. Proven winner | C4: - Video - Ad - 1 - Copy | D4: 5. NMN Scaling Campaign (CBO) Feb 14 2026 | E4: 5. Feb 28 (24. Feb 23 USA 10-12) | F4: PAUSED | G4: 2026-02-28 | H4: 1607918377022076 | I4: 36342.32 | J4: 866 | K4: 53976.31 | L4: 1.485219 | M4: 41.97 | N4: 0.04720497 | O4: 112.66 | P4: 1.770856 | Q4: 322572 | R4: 15227 | S4: 2557 | T4: 1905 | U4: 297219 | V4: 57700
A5: 120251692693440341 | B5: =IF(AND(I5>='Read Me & Markers'!$B$18,J5>='Read Me & Markers'!$B$19,L5>='Read Me & Markers'!$B$20),"A. Proven winner",IF(AND(I5>='Read Me & Markers'!$B$18,J5>='Read Me & Markers'!$B$19,L5>='Read Me & Markers'!$B$21),"B. Strong performer",IF(AND(I5>='Read Me & Markers'!$B$22,L5>='Read Me & Markers'!$B$23),"C. Scale workhorse",IF(AND(I5>='Read Me & Markers'!$B$24,I5<'Read Me & Markers'!$B$18,J5>='Read Me & Markers'!$B$25,L5>='Read Me & Markers'!$B$26),"D. Promising (needs more spend)","")))) -> C. Scale workhorse | C5: - Video - Ad -2 - Copy | D5: 9. NMN Scale Campaign (CBO) June 27 2026 | E5: 5. (57. March 16 USA 4-6 - Video Ad -2) | F5: PAUSED | G5: 2026-06-27 | H5: 1040744398420375 | I5: 19526.1 | J5: 318 | K5: 21345.86 | L5: 1.093196 | M5: 61.4 | N5: 0.02969702 | O5: 96.13 | P5: 2.511878 | Q5: 203118 | R5: 6032 | S5: 321 | T5: 809 | U5: 169219 | V5: 9412
A6: 120242308889180341 | B6: =IF(AND(I6>='Read Me & Markers'!$B$18,J6>='Read Me & Markers'!$B$19,L6>='Read Me & Markers'!$B$20),"A. Proven winner",IF(AND(I6>='Read Me & Markers'!$B$18,J6>='Read Me & Markers'!$B$19,L6>='Read Me & Markers'!$B$21),"B. Strong performer",IF(AND(I6>='Read Me & Markers'!$B$22,L6>='Read Me & Markers'!$B$23),"C. Scale workhorse",IF(AND(I6>='Read Me & Markers'!$B$24,I6<'Read Me & Markers'!$B$18,J6>='Read Me & Markers'!$B$25,L6>='Read Me & Markers'!$B$26),"D. Promising (needs more spend)","")))) -> A. Proven winner | C6: - Video - Ad - 3 | D6: 4. N2 Testing Campaign (CBO) Jan 27 2026 | E6: Jan 27 USA 7-9 | F6: WITH_ISSUES | G6: 2026-01-27 | H6: 877567944890755 | I6: 16480.85 | J6: 395 | K6: 22893.89 | L6: 1.389121 | M6: 41.72 | N6: 0.06919453 | O6: 87.84 | P6: 1.09498 | Q6: 187616 | R6: 12982 | S6: 1023 | T6: 790 | U6: 180193 | V6: 71708
A7: 120253703126990341 | B7: =IF(AND(I7>='Read Me & Markers'!$B$18,J7>='Read Me & Markers'!$B$19,L7>='Read Me & Markers'!$B$20),"A. Proven winner",IF(AND(I7>='Read Me & Markers'!$B$18,J7>='Read Me & Markers'!$B$19,L7>='Read Me & Markers'!$B$21),"B. Strong performer",IF(AND(I7>='Read Me & Markers'!$B$22,L7>='Read Me & Markers'!$B$23),"C. Scale workhorse",IF(AND(I7>='Read Me & Markers'!$B$24,I7<'Read Me & Markers'!$B$18,J7>='Read Me & Markers'!$B$25,L7>='Read Me & Markers'!$B$26),"D. Promising (needs more spend)","")))) | C7: 7. 20260902_MilitaryTakesWhat_V1 | D7: 8. NMN Testing Campaign (CBO) June 21 2026 | E7: 59. Broad_USA_Creative Testing | F7: PAUSED | G7: 2026-09-01 | H7: 951257170590634 | I7: 13721.3 | J7: 148 | K7: 7298.49 | L7: 0.53191 | M7: 92.71 | N7: 0.04914259 | O7: 159.52 | P7: 1.298987 | Q7: 86015 | R7: 4227 | S7: 389 | T7: 397 | U7: 81160 | V7: 31243
A8: 120243160670300341 | B8: =IF(AND(I8>='Read Me & Markers'!$B$18,J8>='Read Me & Markers'!$B$19,L8>='Read Me & Markers'!$B$20),"A. Proven winner",IF(AND(I8>='Read Me & Markers'!$B$18,J8>='Read Me & Markers'!$B$19,L8>='Read Me & Markers'!$B$21),"B. Strong performer",IF(AND(I8>='Read Me & Markers'!$B$22,L8>='Read Me & Markers'!$B$23),"C. Scale workhorse",IF(AND(I8>='Read Me & Markers'!$B$24,I8<'Read Me & Markers'!$B$18,J8>='Read Me & Markers'!$B$25,L8>='Read Me & Markers'!$B$26),"D. Promising (needs more spend)","")))) -> B. Strong performer | C8: - Video - Ad - 1 - Copy | D8: 5. NMN Scaling Campaign (CBO) Feb 14 2026 | E8: 2. Feb 19 (12. Feb 6 USA 16-18) | F8: PAUSED | G8: 2026-02-19 | H8: 1277267117282690 | I8: 13539.24 | J8: 262 | K8: 16514.4 | L8: 1.219744 | M8: 51.68 | N8: 0.02535233 | O8: 69.64 | P8: 2.204808 | Q8: 194420 | R8: 4929 | S8: 763 | T8: 626 | U8: 173129 | V8: 7139
