Workbook

Sheet Quote Bank
A1: ID | B1: Customer's own words | C1: Words | D1: Brand / SKU | E1: Source | F1: Provenance | G1: Emotion | H1: Job to be done | I1: Objection or Benefit | J1: Trigger moment | K1: Time/place | L1: Physical | M1: Former self | N1: Admission | O1: Plain | P1: <12 words | Q1: Marker score | R1: Verdict | S1: Angle
A2: Q001 | B2: After researching the ingredients and company behind this supplement I feel confident taking it. | C2: =IF(LEN(TRIM(B2))=0,0,LEN(TRIM(B2))-LEN(SUBSTITUTE(TRIM(B2)," ",""))+1) | D2: ProHealth NMN Pro (Uthever) | E2: Mark B · 4★ · Jul 2026 · Vine | F2: Verbatim | G2: Pride | H2: Be the person who did the research | I2: BENEFIT · Credentialed brand | J2: Pre-purchase research | O2: Y | P2: =IF(C2<12,"Y","") | Q2: =COUNTIF(K2:P2,"Y") | R2: =IF(Q2>=3,"USE","CONTEXT") | S2: A7 Honest science
A3: Q002 | B3: I also looked at the broader science to see if NMN is just hype. | C3: =IF(LEN(TRIM(B3))=0,0,LEN(TRIM(B3))-LEN(SUBSTITUTE(TRIM(B3)," ",""))+1) | D3: ProHealth NMN Pro (Uthever) | E3: Mark B · 4★ · Jul 2026 · Vine | F3: Verbatim | G3: Fear | H3: Verify it's real and safe | I3: OBJECTION · Category is hype | J3: Pre-purchase research | N3: Y | O3: Y | P3: =IF(C3<12,"Y","") | Q3: =COUNTIF(K3:P3,"Y") | R3: =IF(Q3>=3,"USE","CONTEXT") | S3: A7 Honest science
A4: Q003 | B4: The honest answer is that the science is real but still emerging. | C4: =IF(LEN(TRIM(B4))=0,0,LEN(TRIM(B4))-LEN(SUBSTITUTE(TRIM(B4)," ",""))+1) | D4: ProHealth NMN Pro (Uthever) | E4: Mark B · 4★ · Jul 2026 · Vine | F4: Verbatim | G4: Hope | H4: Verify it's real and safe | I4: OBJECTION · Evidence immature | J4: Pre-purchase research | O4: Y | P4: =IF(C4<12,"Y","") | Q4: =COUNTIF(K4:P4,"Y") | R4: =IF(Q4>=3,"USE","CONTEXT") | S4: A7 Honest science
A5: Q004 | B5: It is not snake oil but the anti aging claims are ahead of the evidence. | C5: =IF(LEN(TRIM(B5))=0,0,LEN(TRIM(B5))-LEN(SUBSTITUTE(TRIM(B5)," ",""))+1) | D5: ProHealth NMN Pro (Uthever) | E5: Mark B · 4★ · Jul 2026 · Vine | F5: Verbatim | G5: Fear | H5: Verify it's real and safe | I5: OBJECTION · Marketing overreach | J5: Comparing brands | O5: Y | P5: =IF(C5<12,"Y","") | Q5: =COUNTIF(K5:P5,"Y") | R5: =IF(Q5>=3,"USE","CONTEXT") | S5: A7 Honest science
A6: Q005 | B6: A 2025 meta analysis found no clear benefit for muscle strength or metabolic markers. | C6: =IF(LEN(TRIM(B6))=0,0,LEN(TRIM(B6))-LEN(SUBSTITUTE(TRIM(B6)," ",""))+1) | D6: ProHealth NMN Pro (Uthever) | E6: Mark B · 4★ · Jul 2026 · Vine | F6: Verbatim | G6: Fear | H6: Verify it's real and safe | I6: OBJECTION · Evidence immature | J6: Pre-purchase research | P6: =IF(C6<12,"Y","") | Q6: =COUNTIF(K6:P6,"Y") | R6: =IF(Q6>=3,"USE","CONTEXT") | S6: A7 Honest science
A7: Q006 | B7: The FDA reversed its 2022 ban and now allows NMN as a supplement. | C7: =IF(LEN(TRIM(B7))=0,0,LEN(TRIM(B7))-LEN(SUBSTITUTE(TRIM(B7)," ",""))+1) | D7: ProHealth NMN Pro (Uthever) | E7: Mark B · 4★ · Jul 2026 · Vine | F7: Verbatim | G7: Relief | H7: Verify it's real and safe | I7: OBJECTION · Was NMN banned? | J7: Pre-purchase research | K7: Y | P7: =IF(C7<12,"Y","") | Q7: =COUNTIF(K7:P7,"Y") | R7: =IF(Q7>=3,"USE","CONTEXT") | S7: A7 Honest science
A8: Q007 | B8: Perhaps in another year or two the effectiveness will be demonstrated in clinical testing. | C8: =IF(LEN(TRIM(B8))=0,0,LEN(TRIM(B8))-LEN(SUBSTITUTE(TRIM(B8)," ",""))+1) | D8: ProHealth NMN Pro (Uthever) | E8: Mark B · 4★ · Jul 2026 · Vine | F8: Verbatim | G8: Hope | H8: Know whether it's working | I8: OBJECTION · Evidence immature | J8: Reorder decision | K8: Y | O8: Y | P8: =IF(C8<12,"Y","") | Q8: =COUNTIF(K8:P8,"Y") | R8: =IF(Q8>=3,"USE","CONTEXT") | S8: A7 Honest science
A9: Q008 | B9: The marketing leans on benefits that are still being studied. | C9: =IF(LEN(TRIM(B9))=0,0,LEN(TRIM(B9))-LEN(SUBSTITUTE(TRIM(B9)," ",""))+1) | D9: ProHealth NMN Pro (Uthever) | E9: Mark B · 4★ · Jul 2026 · Vine | F9: Verbatim | G9: Anger | H9: Not get ripped off | I9: OBJECTION · Marketing overreach | J9: Warning others | O9: Y | P9: =IF(C9<12,"Y","") | Q9: =COUNTIF(K9:P9,"Y") | R9: =IF(Q9>=3,"USE","CONTEXT") | S9: A7 Honest science
A10: Q009 | B10: TMG supports methylation which is important because NMN supplementation can deplete methyl groups. | C10: =IF(LEN(TRIM(B10))=0,0,LEN(TRIM(B10))-LEN(SUBSTITUTE(TRIM(B10)," ",""))+1) | D10: ProHealth NMN Pro (Uthever) | E10: Mark B · 4★ · Jul 2026 · Vine | F10: Verbatim | G10: Pride | H10: Be the person who did the research | I10: BENEFIT · Cofactors included | J10: Reading the label | P10: =IF(C10<12,"Y","") | Q10: =COUNTIF(K10:P10,"Y") | R10: =IF(Q10>=3,"USE","CONTEXT") | S10: A6 Retire the shelf
A11: Q010 | B11: Having all three in one bottle is convenient and actually costs less than buying them separately. | C11: =IF(LEN(TRIM(B11))=0,0,LEN(TRIM(B11))-LEN(SUBSTITUTE(TRIM(B11)," ",""))+1) | D11: ProHealth NMN Pro (Uthever) | E11: Mark B · 4★ · Jul 2026 · Vine | F11: Verbatim | G11: Relief | H11: Simplify my routine | I11: BENEFIT · Consolidation | J11: Doing the price math | O11: Y | P11: =IF(C11<12,"Y","") | Q11: =COUNTIF(K11:P11,"Y") | R11: =IF(Q11>=3,"USE","CONTEXT") | S11: A6 Retire the shelf
A12: Q011 | B12: This is a well thought out stack. | C12: =IF(LEN(TRIM(B12))=0,0,LEN(TRIM(B12))-LEN(SUBSTITUTE(TRIM(B12)," ",""))+1) | D12: ProHealth NMN Pro (Uthever) | E12: Mark B · 4★ · Jul 2026 · Vine | F12: Verbatim | G12: Pride | H12: Simplify my routine | I12: BENEFIT · Formula design | J12: Reading the label | O12: Y | P12: =IF(C12<12,"Y","") | Q12: =COUNTIF(K12:P12,"Y") | R12: =IF(Q12>=3,"USE","CONTEXT") | S12: A6 Retire the shelf
A13: Q012 | B13: The capsules are easy to swallow and have no unpleasant taste. | C13: =IF(LEN(TRIM(B13))=0,0,LEN(TRIM(B13))-LEN(SUBSTITUTE(TRIM(B13)," ",""))+1) | D13: ProHealth NMN Pro (Uthever) | E13: Mark B · 4★ · Jul 2026 · Vine | F13: Verbatim | G13: Relief | H13: Protect a sensitive body | I13: BENEFIT · Sensory ease | J13: First dose | L13: Y | O13: Y | P13: =IF(C13<12,"Y","") | Q13: =COUNTIF(K13:P13,"Y") | R13: =IF(Q13>=3,"USE","CONTEXT") | S13: A5 Gentle start
A14: Q013 | B14: I have noticed slight improved energy levels since starting. | C14: =IF(LEN(TRIM(B14))=0,0,LEN(TRIM(B14))-LEN(SUBSTITUTE(TRIM(B14)," ",""))+1) | D14: ProHealth NMN Pro (Uthever) | E14: Mark B · 4★ · Jul 2026 · Vine | F14: Verbatim | G14: Hope | H14: Get my energy back | I14: BENEFIT · Mild energy | J14: Weeks 2–4 | L14: Y | O14: Y | P14: =IF(C14<12,"Y","") | Q14: =COUNTIF(K14:P14,"Y") | R14: =IF(Q14>=3,"USE","CONTEXT") | S14: A1 You won't feel it
A15: Q014 | B15: The 3 pack provides a 6 month supply at about 232 dollars which is premium pricing. | C15: =IF(LEN(TRIM(B15))=0,0,LEN(TRIM(B15))-LEN(SUBSTITUTE(TRIM(B15)," ",""))+1) | D15: ProHealth NMN Pro (Uthever) | E15: Mark B · 4★ · Jul 2026 · Vine | F15: Verbatim | G15: Anger | H15: Justify the ongoing spend | I15: OBJECTION · Cost per day | J15: Doing the price math | O15: Y | P15: =IF(C15<12,"Y","") | Q15: =COUNTIF(K15:P15,"Y") | R15: =IF(Q15>=3,"USE","CONTEXT") | S15: A3 Do the math
A16: Q015 | B16: ProHealth has been around since 1988 and is a BBB A plus rated company. | C16: =IF(LEN(TRIM(B16))=0,0,LEN(TRIM(B16))-LEN(SUBSTITUTE(TRIM(B16)," ",""))+1) | D16: ProHealth NMN Pro (Uthever) | E16: Mark B · 4★ · Jul 2026 · Vine | F16: Verbatim | G16: Relief | H16: Verify it's real and safe | I16: BENEFIT · Track record | J16: Comparing brands | K16: Y | P16: =IF(C16<12,"Y","") | Q16: =COUNTIF(K16:P16,"Y") | R16: =IF(Q16>=3,"USE","CONTEXT") | S16: A2 The receipt
A17: Q016 | B17: I take a lot of supplements and am very focused on metabolically healthy aging as I am approaching 60. | C17: =IF(LEN(TRIM(B17))=0,0,LEN(TRIM(B17))-LEN(SUBSTITUTE(TRIM(B17)," ",""))+1) | D17: ProHealth NMN Pro (Uthever) | E17: kLr · 4★ · Jun 2026 · Vine | F17: Verbatim | G17: Fear | H17: Stay functional as I age | I17: BENEFIT · Identity fit | J17: Pre-purchase research | K17: Y | M17: Y | P17: =IF(C17<12,"Y","") | Q17: =COUNTIF(K17:P17,"Y") | R17: =IF(Q17>=3,"USE","CONTEXT") | S17: A6 Retire the shelf
A18: Q017 | B18: They can add up, so it's important to me that they are not just effective, but a good value proposition and safe. | C18: =IF(LEN(TRIM(B18))=0,0,LEN(TRIM(B18))-LEN(SUBSTITUTE(TRIM(B18)," ",""))+1) | D18: ProHealth NMN Pro (Uthever) | E18: kLr · 4★ · Jun 2026 · Vine | F18: Verbatim | G18: Anger | H18: Justify the ongoing spend | I18: OBJECTION · Stack tax | J18: Doing the price math | O18: Y | P18: =IF(C18<12,"Y","") | Q18: =COUNTIF(K18:P18,"Y") | R18: =IF(Q18>=3,"USE","CONTEXT") | S18: A3 Do the math
A19: Q018 | B19: It's often hard to quantify changes in the short term on an individual basis. | C19: =IF(LEN(TRIM(B19))=0,0,LEN(TRIM(B19))-LEN(SUBSTITUTE(TRIM(B19)," ",""))+1) | D19: ProHealth NMN Pro (Uthever) | E19: kLr · 4★ · Jun 2026 · Vine | F19: Verbatim | G19: Hope | H19: Know whether it's working | I19: OBJECTION · No feedback loop | J19: Weeks 2–4 | N19: Y | O19: Y | P19: =IF(C19<12,"Y","") | Q19: =COUNTIF(K19:P19,"Y") | R19: =IF(Q19>=3,"USE","CONTEXT") | S19: A1 You won't feel it
A20: Q019 | B20: So many factors come into play in how I may feel on a particular day. | C20: =IF(LEN(TRIM(B20))=0,0,LEN(TRIM(B20))-LEN(SUBSTITUTE(TRIM(B20)," ",""))+1) | D20: ProHealth NMN Pro (Uthever) | E20: kLr · 4★ · Jun 2026 · Vine | F20: Verbatim | G20: Hope | H20: Know whether it's working | I20: OBJECTION · No feedback loop | J20: Weeks 2–4 | L20: Y | N20: Y | O20: Y | P20: =IF(C20<12,"Y","") | Q20: =COUNTIF(K20:P20,"Y") | R20: =IF(Q20>=3,"USE","CONTEXT") | S20: A1 You won't feel it
A21: Q020 | B21: Have I exercised, did I sleep well, am I stressed, did I drink alcohol the day before? | C21: =IF(LEN(TRIM(B21))=0,0,LEN(TRIM(B21))-LEN(SUBSTITUTE(TRIM(B21)," ",""))+1) | D21: ProHealth NMN Pro (Uthever) | E21: kLr · 4★ · Jun 2026 · Vine | F21: Verbatim | G21: Shame | H21: Know whether it's working | I21: OBJECTION · No feedback loop | J21: Weeks 2–4 | L21: Y | N21: Y | O21: Y | P21: =IF(C21<12,"Y","") | Q21: =COUNTIF(K21:P21,"Y") | R21: =IF(Q21>=3,"USE","CONTEXT") | S21: A1 You won't feel it
A22: Q021 | B22: I consider this a long-term health optimizer. | C22: =IF(LEN(TRIM(B22))=0,0,LEN(TRIM(B22))-LEN(SUBSTITUTE(TRIM(B22)," ",""))+1) | D22: ProHealth NMN Pro (Uthever) | E22: kLr · 4★ · Jun 2026 · Vine | F22: Verbatim | G22: Hope | H22: Stay functional as I age | I22: BENEFIT · Insurance frame | J22: Reorder decision | O22: Y | P22: =IF(C22<12,"Y","") | Q22: =COUNTIF(K22:P22,"Y") | R22: =IF(Q22>=3,"USE","CONTEXT") | S22: A1 You won't feel it
A23: Q022 | B23: I am very interested in giving my body the resources it needs to have the best outcome it can have as I age. | C23: =IF(LEN(TRIM(B23))=0,0,LEN(TRIM(B23))-LEN(SUBSTITUTE(TRIM(B23)," ",""))+1) | D23: ProHealth NMN Pro (Uthever) | E23: kLr · 4★ · Jun 2026 · Vine | F23: Verbatim | G23: Hope | H23: Stay functional as I age | I23: BENEFIT · Insurance frame | J23: Reorder decision | L23: Y | O23: Y | P23: =IF(C23<12,"Y","") | Q23: =COUNTIF(K23:P23,"Y") | R23: =IF(Q23>=3,"USE","CONTEXT") | S23: A1 You won't feel it
A24: Q023 | B24: I am not new to these. | C24: =IF(LEN(TRIM(B24))=0,0,LEN(TRIM(B24))-LEN(SUBSTITUTE(TRIM(B24)," ",""))+1) | D24: ProHealth NMN Pro (Uthever) | E24: kLr · 4★ · Jun 2026 · Vine | F24: Verbatim | G24: Pride | H24: Be the person who did the research | I24: BENEFIT · Self-image | J24: Comparing brands | M24: Y | O24: Y | P24: =IF(C24<12,"Y","") | Q24: =COUNTIF(K24:P24,"Y") | R24: =IF(Q24>=3,"USE","CONTEXT") | S24: A4 Dose is the product
A25: Q024 | B25: One might alternate both forms to get some of these benefits without totally breaking the budget. | C25: =IF(LEN(TRIM(B25))=0,0,LEN(TRIM(B25))-LEN(SUBSTITUTE(TRIM(B25)," ",""))+1) | D25: ProHealth NMN Pro (Uthever) | E25: kLr · 4★ · Jun 2026 · Vine | F25: Verbatim | G25: Shame | H25: Justify the ongoing spend | I25: OBJECTION · Cost per day | J25: Doing the price math | N25: Y | O25: Y | P25: =IF(C25<12,"Y","") | Q25: =COUNTIF(K25:P25,"Y") | R25: =IF(Q25>=3,"USE","CONTEXT") | S25: A3 Do the math
A26: Q025 | B26: Lot tested, with public batch-specific certificates. | C26: =IF(LEN(TRIM(B26))=0,0,LEN(TRIM(B26))-LEN(SUBSTITUTE(TRIM(B26)," ",""))+1) | D26: ProHealth NMN Pro (Uthever) | E26: kLr · 4★ · Jun 2026 · Vine | F26: Verbatim | G26: Relief | H26: Verify it's real and safe | I26: BENEFIT · Batch COA | J26: Pre-purchase research | P26: =IF(C26<12,"Y","") | Q26: =COUNTIF(K26:P26,"Y") | R26: =IF(Q26>=3,"USE","CONTEXT") | S26: A2 The receipt
A27: Q026 | B27: Lot number and Best By date is printed on the bottle. | C27: =IF(LEN(TRIM(B27))=0,0,LEN(TRIM(B27))-LEN(SUBSTITUTE(TRIM(B27)," ",""))+1) | D27: ProHealth NMN Pro (Uthever) | E27: kLr · 4★ · Jun 2026 · Vine | F27: Verbatim | G27: Relief | H27: Verify it's real and safe | I27: BENEFIT · Expiry printed | J27: Unboxing / first inspection | O27: Y | P27: =IF(C27<12,"Y","") | Q27: =COUNTIF(K27:P27,"Y") | R27: =IF(Q27>=3,"USE","CONTEXT") | S27: A2 The receipt
A28: Q027 | B28: It is confirmed made at a cGMP third-party certified facility. | C28: =IF(LEN(TRIM(B28))=0,0,LEN(TRIM(B28))-LEN(SUBSTITUTE(TRIM(B28)," ",""))+1) | D28: ProHealth NMN Pro (Uthever) | E28: kLr · 4★ · Jun 2026 · Vine | F28: Verbatim | G28: Relief | H28: Verify it's real and safe | I28: BENEFIT · Manufacturing | J28: Pre-purchase research | P28: =IF(C28<12,"Y","") | Q28: =COUNTIF(K28:P28,"Y") | R28: =IF(Q28>=3,"USE","CONTEXT") | S28: A2 The receipt
A29: Q028 | B29: 300 mg a day for 60 days in 66 adults, a 38% NAD+ increase by day 60. | C29: =IF(LEN(TRIM(B29))=0,0,LEN(TRIM(B29))-LEN(SUBSTITUTE(TRIM(B29)," ",""))+1) | D29: ProHealth NMN Pro (Uthever) | E29: kLr · 4★ · Jun 2026 · Vine | F29: Verbatim | G29: Pride | H29: Be the person who did the research | I29: BENEFIT · Human RCT | J29: Reading the label | K29: Y | P29: =IF(C29<12,"Y","") | Q29: =COUNTIF(K29:P29,"Y") | R29: =IF(Q29>=3,"USE","CONTEXT") | S29: A4 Dose is the product
A30: Q029 | B30: Results vary by interpretation, dose and duration. | C30: =IF(LEN(TRIM(B30))=0,0,LEN(TRIM(B30))-LEN(SUBSTITUTE(TRIM(B30)," ",""))+1) | D30: ProHealth NMN Pro (Uthever) | E30: kLr · 4★ · Jun 2026 · Vine | F30: Verbatim | G30: Fear | H30: Know whether it's working | I30: OBJECTION · Evidence immature | J30: Pre-purchase research | O30: Y | P30: =IF(C30<12,"Y","") | Q30: =COUNTIF(K30:P30,"Y") | R30: =IF(Q30>=3,"USE","CONTEXT") | S30: A7 Honest science
A31: Q030 | B31: Liposomal delivery is supposed to enhance absorption. | C31: =IF(LEN(TRIM(B31))=0,0,LEN(TRIM(B31))-LEN(SUBSTITUTE(TRIM(B31)," ",""))+1) | D31: ProHealth NMN Pro (Uthever) | E31: kLr · 4★ · Jun 2026 · Vine | F31: Verbatim | G31: Hope | H31: Verify it's real and safe | I31: OBJECTION · Absorption claim | J31: Reading the label | P31: =IF(C31<12,"Y","") | Q31: =COUNTIF(K31:P31,"Y") | R31: =IF(Q31>=3,"USE","CONTEXT") | S31: A4 Dose is the product
A32: Q031 | B32: Depending on how much you wish to take, one bottle could last weeks or months. | C32: =IF(LEN(TRIM(B32))=0,0,LEN(TRIM(B32))-LEN(SUBSTITUTE(TRIM(B32)," ",""))+1) | D32: ProHealth NMN Pro (Uthever) | E32: kLr · 4★ · Jun 2026 · Vine | F32: Verbatim | G32: Fear | H32: Justify the ongoing spend | I32: OBJECTION · True supply length | J32: Doing the price math | O32: Y | P32: =IF(C32<12,"Y","") | Q32: =COUNTIF(K32:P32,"Y") | R32: =IF(Q32>=3,"USE","CONTEXT") | S32: A3 Do the math
A33: Q032 | B33: I kind of had high hopes for this longevity supplement. | C33: =IF(LEN(TRIM(B33))=0,0,LEN(TRIM(B33))-LEN(SUBSTITUTE(TRIM(B33)," ",""))+1) | D33: ProHealth NMN Pro (Uthever) | E33: Nancy Taylor · 3★ · Jul 2026 | F33: Verbatim | G33: Grief | H33: Know whether it's working | I33: OBJECTION · Unmet expectation | J33: Weeks 2–4 | N33: Y | O33: Y | P33: =IF(C33<12,"Y","") | Q33: =COUNTIF(K33:P33,"Y") | R33: =IF(Q33>=3,"USE","CONTEXT") | S33: A1 You won't feel it
A34: Q033 | B34: I'm not feeling any different energy wise. | C34: =IF(LEN(TRIM(B34))=0,0,LEN(TRIM(B34))-LEN(SUBSTITUTE(TRIM(B34)," ",""))+1) | D34: ProHealth NMN Pro (Uthever) | E34: Nancy Taylor · 3★ · Jul 2026 | F34: Verbatim | G34: Grief | H34: Get my energy back | I34: OBJECTION · Felt nothing | J34: Weeks 2–4 | L34: Y | O34: Y | P34: =IF(C34<12,"Y","") | Q34: =COUNTIF(K34:P34,"Y") | R34: =IF(Q34>=3,"USE","CONTEXT") | S34: A1 You won't feel it
A35: Q034 | B35: But maybe I need to give it more time? | C35: =IF(LEN(TRIM(B35))=0,0,LEN(TRIM(B35))-LEN(SUBSTITUTE(TRIM(B35)," ",""))+1) | D35: ProHealth NMN Pro (Uthever) | E35: Nancy Taylor · 3★ · Jul 2026 | F35: Verbatim | G35: Hope | H35: Know whether it's working | I35: OBJECTION · Timeline unclear | J35: Weeks 2–4 | N35: Y | O35: Y | P35: =IF(C35<12,"Y","") | Q35: =COUNTIF(K35:P35,"Y") | R35: =IF(Q35>=3,"USE","CONTEXT") | S35: A1 You won't feel it
A36: Q035 | B36: It's not inexpensive so I probably won't be ordering again. | C36: =IF(LEN(TRIM(B36))=0,0,LEN(TRIM(B36))-LEN(SUBSTITUTE(TRIM(B36)," ",""))+1) | D36: ProHealth NMN Pro (Uthever) | E36: Nancy Taylor · 3★ · Jul 2026 | F36: Verbatim | G36: Anger | H36: Justify the ongoing spend | I36: OBJECTION · Cost per day | J36: Reorder decision | O36: Y | P36: =IF(C36<12,"Y","") | Q36: =COUNTIF(K36:P36,"Y") | R36: =IF(Q36>=3,"USE","CONTEXT") | S36: A3 Do the math
A37: Q036 | B37: Was hoping to notice a change while taking. | C37: =IF(LEN(TRIM(B37))=0,0,LEN(TRIM(B37))-LEN(SUBSTITUTE(TRIM(B37)," ",""))+1) | D37: ProHealth NMN Pro (Uthever) | E37: Nancy Taylor · 3★ · Jul 2026 | F37: Verbatim | G37: Grief | H37: Know whether it's working | I37: OBJECTION · Felt nothing | J37: Weeks 2–4 | L37: Y | N37: Y | O37: Y | P37: =IF(C37<12,"Y","") | Q37: =COUNTIF(K37:P37,"Y") | R37: =IF(Q37>=3,"USE","CONTEXT") | S37: A1 You won't feel it
A38: Q037 | B38: As recommended by the bottle I took two pills around 8am. | C38: =IF(LEN(TRIM(B38))=0,0,LEN(TRIM(B38))-LEN(SUBSTITUTE(TRIM(B38)," ",""))+1) | D38: ProHealth NMN Pro (Uthever) | E38: Matthew B · 1★ · Mar 2022 | F38: Verbatim | G38: Anger | H38: Protect a sensitive body | I38: OBJECTION · Dose guidance | J38: First dose | K38: Y | O38: Y | P38: =IF(C38<12,"Y","") | Q38: =COUNTIF(K38:P38,"Y") | R38: =IF(Q38>=3,"USE","CONTEXT") | S38: A5 Gentle start
A39: Q038 | B39: I was unable to fall asleep until 6am the following morning. | C39: =IF(LEN(TRIM(B39))=0,0,LEN(TRIM(B39))-LEN(SUBSTITUTE(TRIM(B39)," ",""))+1) | D39: ProHealth NMN Pro (Uthever) | E39: Matthew B · 1★ · Mar 2022 | F39: Verbatim | G39: Anger | H39: Sleep through the night | I39: OBJECTION · Insomnia | J39: First dose | K39: Y | L39: Y | O39: Y | P39: =IF(C39<12,"Y","") | Q39: =COUNTIF(K39:P39,"Y") | R39: =IF(Q39>=3,"USE","CONTEXT") | S39: A5 Gentle start
A40: Q039 | B40: I experienced an increase in energy, an increase in heart rate, and anxiousness. | C40: =IF(LEN(TRIM(B40))=0,0,LEN(TRIM(B40))-LEN(SUBSTITUTE(TRIM(B40)," ",""))+1) | D40: ProHealth NMN Pro (Uthever) | E40: Matthew B · 1★ · Mar 2022 | F40: Verbatim | G40: Fear | H40: Protect a sensitive body | I40: OBJECTION · Over-stimulation | J40: First dose | L40: Y | O40: Y | P40: =IF(C40<12,"Y","") | Q40: =COUNTIF(K40:P40,"Y") | R40: =IF(Q40>=3,"USE","CONTEXT") | S40: A5 Gentle start
...

Sheet Rollups
A1: Where the emotional weight sits
A2: All counts are live formulas over the Quote Bank sheet.
A4: By emotion
A5: Emotion | B5: Quotes | C5: Usable (score 3+)
A6: Fear | B6: =COUNTIF('Quote Bank'!$G$2:$G$190,A6) | C6: =COUNTIFS('Quote Bank'!$G$2:$G$190,A6,'Quote Bank'!$R$2:$R$190,"USE")
A7: Shame | B7: =COUNTIF('Quote Bank'!$G$2:$G$190,A7) | C7: =COUNTIFS('Quote Bank'!$G$2:$G$190,A7,'Quote Bank'!$R$2:$R$190,"USE")
A8: Hope | B8: =COUNTIF('Quote Bank'!$G$2:$G$190,A8) | C8: =COUNTIFS('Quote Bank'!$G$2:$G$190,A8,'Quote Bank'!$R$2:$R$190,"USE")
A9: Relief | B9: =COUNTIF('Quote Bank'!$G$2:$G$190,A9) | C9: =COUNTIFS('Quote Bank'!$G$2:$G$190,A9,'Quote Bank'!$R$2:$R$190,"USE")
A10: Pride | B10: =COUNTIF('Quote Bank'!$G$2:$G$190,A10) | C10: =COUNTIFS('Quote Bank'!$G$2:$G$190,A10,'Quote Bank'!$R$2:$R$190,"USE")
A11: Anger | B11: =COUNTIF('Quote Bank'!$G$2:$G$190,A11) | C11: =COUNTIFS('Quote Bank'!$G$2:$G$190,A11,'Quote Bank'!$R$2:$R$190,"USE")
A12: Grief | B12: =COUNTIF('Quote Bank'!$G$2:$G$190,A12) | C12: =COUNTIFS('Quote Bank'!$G$2:$G$190,A12,'Quote Bank'!$R$2:$R$190,"USE")
A15: By job to be done
A16: Job to be done | B16: Quotes | C16: Usable (score 3+)
A17: Be the person who did the research | B17: =COUNTIF('Quote Bank'!$H$2:$H$190,A17) | C17: =COUNTIFS('Quote Bank'!$H$2:$H$190,A17,'Quote Bank'!$R$2:$R$190,"USE")
A18: Care for my spouse | B18: =COUNTIF('Quote Bank'!$H$2:$H$190,A18) | C18: =COUNTIFS('Quote Bank'!$H$2:$H$190,A18,'Quote Bank'!$R$2:$R$190,"USE")
A19: Get my energy back | B19: =COUNTIF('Quote Bank'!$H$2:$H$190,A19) | C19: =COUNTIFS('Quote Bank'!$H$2:$H$190,A19,'Quote Bank'!$R$2:$R$190,"USE")
A20: Justify the ongoing spend | B20: =COUNTIF('Quote Bank'!$H$2:$H$190,A20) | C20: =COUNTIFS('Quote Bank'!$H$2:$H$190,A20,'Quote Bank'!$R$2:$R$190,"USE")
A21: Know whether it's working | B21: =COUNTIF('Quote Bank'!$H$2:$H$190,A21) | C21: =COUNTIFS('Quote Bank'!$H$2:$H$190,A21,'Quote Bank'!$R$2:$R$190,"USE")
A22: Not get ripped off | B22: =COUNTIF('Quote Bank'!$H$2:$H$190,A22) | C22: =COUNTIFS('Quote Bank'!$H$2:$H$190,A22,'Quote Bank'!$R$2:$R$190,"USE")
A23: Protect a sensitive body | B23: =COUNTIF('Quote Bank'!$H$2:$H$190,A23) | C23: =COUNTIFS('Quote Bank'!$H$2:$H$190,A23,'Quote Bank'!$R$2:$R$190,"USE")
A24: Simplify my routine | B24: =COUNTIF('Quote Bank'!$H$2:$H$190,A24) | C24: =COUNTIFS('Quote Bank'!$H$2:$H$190,A24,'Quote Bank'!$R$2:$R$190,"USE")
A25: Sleep through the night | B25: =COUNTIF('Quote Bank'!$H$2:$H$190,A25) | C25: =COUNTIFS('Quote Bank'!$H$2:$H$190,A25,'Quote Bank'!$R$2:$R$190,"USE")
A26: Slow visible aging | B26: =COUNTIF('Quote Bank'!$H$2:$H$190,A26) | C26: =COUNTIFS('Quote Bank'!$H$2:$H$190,A26,'Quote Bank'!$R$2:$R$190,"USE")
A27: Stay functional as I age | B27: =COUNTIF('Quote Bank'!$H$2:$H$190,A27) | C27: =COUNTIFS('Quote Bank'!$H$2:$H$190,A27,'Quote Bank'!$R$2:$R$190,"USE")
A28: Think clearly again | B28: =COUNTIF('Quote Bank'!$H$2:$H$190,A28) | C28: =COUNTIFS('Quote Bank'!$H$2:$H$190,A28,'Quote Bank'!$R$2:$R$190,"USE")
A29: Verify it's real and safe | B29: =COUNTIF('Quote Bank'!$H$2:$H$190,A29) | C29: =COUNTIFS('Quote Bank'!$H$2:$H$190,A29,'Quote Bank'!$R$2:$R$190,"USE")
A32: By trigger moment
A33: Trigger moment | B33: Quotes | C33: Usable (score 3+)
A34: Pre-purchase research | B34: =COUNTIF('Quote Bank'!$J$2:$J$190,A34) | C34: =COUNTIFS('Quote Bank'!$J$2:$J$190,A34,'Quote Bank'!$R$2:$R$190,"USE")
A35: Comparing brands | B35: =COUNTIF('Quote Bank'!$J$2:$J$190,A35) | C35: =COUNTIFS('Quote Bank'!$J$2:$J$190,A35,'Quote Bank'!$R$2:$R$190,"USE")
A36: Reading the label | B36: =COUNTIF('Quote Bank'!$J$2:$J$190,A36) | C36: =COUNTIFS('Quote Bank'!$J$2:$J$190,A36,'Quote Bank'!$R$2:$R$190,"USE")
A37: Doing the price math | B37: =COUNTIF('Quote Bank'!$J$2:$J$190,A37) | C37: =COUNTIFS('Quote Bank'!$J$2:$J$190,A37,'Quote Bank'!$R$2:$R$190,"USE")
A38: Unboxing / first inspection | B38: =COUNTIF('Quote Bank'!$J$2:$J$190,A38) | C38: =COUNTIFS('Quote Bank'!$J$2:$J$190,A38,'Quote Bank'!$R$2:$R$190,"USE")
A39: First dose | B39: =COUNTIF('Quote Bank'!$J$2:$J$190,A39) | C39: =COUNTIFS('Quote Bank'!$J$2:$J$190,A39,'Quote Bank'!$R$2:$R$190,"USE")
A40: Week 1 | B40: =COUNTIF('Quote Bank'!$J$2:$J$190,A40) | C40: =COUNTIFS('Quote Bank'!$J$2:$J$190,A40,'Quote Bank'!$R$2:$R$190,"USE")
A41: Weeks 2–4 | B41: =COUNTIF('Quote Bank'!$J$2:$J$190,A41) | C41: =COUNTIFS('Quote Bank'!$J$2:$J$190,A41,'Quote Bank'!$R$2:$R$190,"USE")
A42: Month 2+ | B42: =COUNTIF('Quote Bank'!$J$2:$J$190,A42) | C42: =COUNTIFS('Quote Bank'!$J$2:$J$190,A42,'Quote Bank'!$R$2:$R$190,"USE")
A43: Reorder decision | B43: =COUNTIF('Quote Bank'!$J$2:$J$190,A43) | C43: =COUNTIFS('Quote Bank'!$J$2:$J$190,A43,'Quote Bank'!$R$2:$R$190,"USE")
A44: Abandonment / refund | B44: =COUNTIF('Quote Bank'!$J$2:$J$190,A44) | C44: =COUNTIFS('Quote Bank'!$J$2:$J$190,A44,'Quote Bank'!$R$2:$R$190,"USE")
A45: Warning others | B45: =COUNTIF('Quote Bank'!$J$2:$J$190,A45) | C45: =COUNTIFS('Quote Bank'!$J$2:$J$190,A45,'Quote Bank'!$R$2:$R$190,"USE")
...

Sheet How to use this
A1: Voice-of-Customer Bank — how to use it
A3: One quote per row. Tagged so you can filter down to the exact line you need, then write copy that is transcription rather than invention.
A5: The six markers
A6: A quote earns a marker for each of these it contains. Column Q sums them; column R turns that into a verdict.
A8: • Time/place — names a specific hour, day, age or setting. "I took two pills around 8am."
A9: • Physical — a bodily sensation, not an abstraction. "Stomach gurgling loud enough that my coworkers noticed."
A10: • Former self — measures now against a previous version of themselves. "At 65 I needed more energy, not less."
A11: • Admission — something slightly embarrassing to say out loud. "I counted them to be sure."
A12: • Plain — everyday unbranded speech, no jargon, no ingredient names.
A13: • <12 words — computed live from the word count in column C.
A14: The verdict rule
A15: 3 or more markers = USE. These are the lines that can carry an ad, a subject line, or a headline more or less as written. Under 3 = CONTEXT: true and useful for understanding the buyer, but too abstract to run as copy. Roughly a third of the bank clears the bar, which is normal — you are looking for the few dozen lines that sound like a person, not a category.
... A27: The underlying document mixes about ten full verbatim reviews with AI-generated summaries of competitor listings. Percentages quoted in those summaries are directional, not measured. Treat this bank as a language and hypothesis source, then re-run the same tagging on your own reviews, support tickets and refund reasons — that is where the Prime-specific version lives.
